[2024-11-26T15:57:27.415+0000] {taskinstance.py:1159} INFO - Dependencies all met for dep_context=non-requeueable deps ti=<TaskInstance: drift_detection_dag.data_drift_detected manual__2024-11-26T15:56:59.323643+00:00 [queued]>
[2024-11-26T15:57:27.429+0000] {taskinstance.py:1159} INFO - Dependencies all met for dep_context=requeueable deps ti=<TaskInstance: drift_detection_dag.data_drift_detected manual__2024-11-26T15:56:59.323643+00:00 [queued]>
[2024-11-26T15:57:27.429+0000] {taskinstance.py:1361} INFO - Starting attempt 1 of 1
[2024-11-26T15:57:27.447+0000] {taskinstance.py:1382} INFO - Executing <Task(PythonOperator): data_drift_detected> on 2024-11-26 15:56:59.323643+00:00
[2024-11-26T15:57:27.461+0000] {standard_task_runner.py:57} INFO - Started process 314 to run task
[2024-11-26T15:57:27.465+0000] {standard_task_runner.py:84} INFO - Running: ['***', 'tasks', 'run', 'drift_detection_dag', 'data_drift_detected', 'manual__2024-11-26T15:56:59.323643+00:00', '--job-id', '8', '--raw', '--subdir', 'DAGS_FOLDER/drift-detection.py', '--cfg-path', '/tmp/tmpgx6rtwdb']
[2024-11-26T15:57:27.470+0000] {standard_task_runner.py:85} INFO - Job 8: Subtask data_drift_detected
[2024-11-26T15:57:27.552+0000] {task_command.py:416} INFO - Running <TaskInstance: drift_detection_dag.data_drift_detected manual__2024-11-26T15:56:59.323643+00:00 [running]> on host e76aaec22df7
[2024-11-26T15:57:27.650+0000] {taskinstance.py:1662} INFO - Exporting env vars: AIRFLOW_CTX_DAG_OWNER='***' AIRFLOW_CTX_DAG_ID='drift_detection_dag' AIRFLOW_CTX_TASK_ID='data_drift_detected' AIRFLOW_CTX_EXECUTION_DATE='2024-11-26T15:56:59.323643+00:00' AIRFLOW_CTX_TRY_NUMBER='1' AIRFLOW_CTX_DAG_RUN_ID='manual__2024-11-26T15:56:59.323643+00:00'
[2024-11-26T15:57:27.731+0000] {warnings.py:109} WARNING - /home/***/.local/lib/python3.8/site-packages/numpy/lib/function_base.py:2854: RuntimeWarning: invalid value encountered in divide
  c /= stddev[:, None]

[2024-11-26T15:57:27.733+0000] {warnings.py:109} WARNING - /home/***/.local/lib/python3.8/site-packages/numpy/lib/function_base.py:2855: RuntimeWarning: invalid value encountered in divide
  c /= stddev[None, :]

[2024-11-26T15:57:27.745+0000] {warnings.py:109} WARNING - /home/***/.local/lib/python3.8/site-packages/numpy/lib/function_base.py:2854: RuntimeWarning: invalid value encountered in divide
  c /= stddev[:, None]

[2024-11-26T15:57:27.746+0000] {warnings.py:109} WARNING - /home/***/.local/lib/python3.8/site-packages/numpy/lib/function_base.py:2855: RuntimeWarning: invalid value encountered in divide
  c /= stddev[None, :]

[2024-11-26T15:57:27.907+0000] {warnings.py:109} WARNING - /home/***/.local/lib/python3.8/site-packages/numpy/lib/function_base.py:2854: RuntimeWarning: invalid value encountered in divide
  c /= stddev[:, None]

[2024-11-26T15:57:27.908+0000] {warnings.py:109} WARNING - /home/***/.local/lib/python3.8/site-packages/numpy/lib/function_base.py:2855: RuntimeWarning: invalid value encountered in divide
  c /= stddev[None, :]

[2024-11-26T15:57:27.912+0000] {warnings.py:109} WARNING - /home/***/.local/lib/python3.8/site-packages/numpy/lib/function_base.py:2854: RuntimeWarning: invalid value encountered in divide
  c /= stddev[:, None]

[2024-11-26T15:57:27.913+0000] {warnings.py:109} WARNING - /home/***/.local/lib/python3.8/site-packages/numpy/lib/function_base.py:2855: RuntimeWarning: invalid value encountered in divide
  c /= stddev[None, :]

[2024-11-26T15:57:28.070+0000] {python.py:194} INFO - Done. Returned value was: None
[2024-11-26T15:57:28.080+0000] {taskinstance.py:1400} INFO - Marking task as SUCCESS. dag_id=drift_detection_dag, task_id=data_drift_detected, execution_date=20241126T155659, start_date=20241126T155727, end_date=20241126T155728
[2024-11-26T15:57:28.119+0000] {local_task_job_runner.py:228} INFO - Task exited with return code 0
[2024-11-26T15:57:28.157+0000] {taskinstance.py:2778} INFO - 1 downstream tasks scheduled from follow-on schedule check
