[2024-11-26T16:00:16.088+0000] {taskinstance.py:1159} INFO - Dependencies all met for dep_context=non-requeueable deps ti=<TaskInstance: drift_detection_dag.data_drift_detected manual__2024-11-26T15:56:59.323643+00:00 [queued]>
[2024-11-26T16:00:16.109+0000] {taskinstance.py:1159} INFO - Dependencies all met for dep_context=requeueable deps ti=<TaskInstance: drift_detection_dag.data_drift_detected manual__2024-11-26T15:56:59.323643+00:00 [queued]>
[2024-11-26T16:00:16.111+0000] {taskinstance.py:1361} INFO - Starting attempt 2 of 2
[2024-11-26T16:00:16.134+0000] {taskinstance.py:1382} INFO - Executing <Task(PythonOperator): data_drift_detected> on 2024-11-26 15:56:59.323643+00:00
[2024-11-26T16:00:16.148+0000] {standard_task_runner.py:57} INFO - Started process 495 to run task
[2024-11-26T16:00:16.155+0000] {standard_task_runner.py:84} INFO - Running: ['***', 'tasks', 'run', 'drift_detection_dag', 'data_drift_detected', 'manual__2024-11-26T15:56:59.323643+00:00', '--job-id', '15', '--raw', '--subdir', 'DAGS_FOLDER/drift-detection.py', '--cfg-path', '/tmp/tmptvivgv6b']
[2024-11-26T16:00:16.161+0000] {standard_task_runner.py:85} INFO - Job 15: Subtask data_drift_detected
[2024-11-26T16:00:16.248+0000] {task_command.py:416} INFO - Running <TaskInstance: drift_detection_dag.data_drift_detected manual__2024-11-26T15:56:59.323643+00:00 [running]> on host e76aaec22df7
[2024-11-26T16:00:16.365+0000] {taskinstance.py:1662} INFO - Exporting env vars: AIRFLOW_CTX_DAG_OWNER='***' AIRFLOW_CTX_DAG_ID='drift_detection_dag' AIRFLOW_CTX_TASK_ID='data_drift_detected' AIRFLOW_CTX_EXECUTION_DATE='2024-11-26T15:56:59.323643+00:00' AIRFLOW_CTX_TRY_NUMBER='2' AIRFLOW_CTX_DAG_RUN_ID='manual__2024-11-26T15:56:59.323643+00:00'
[2024-11-26T16:00:16.457+0000] {warnings.py:109} WARNING - /home/***/.local/lib/python3.8/site-packages/numpy/lib/function_base.py:2854: RuntimeWarning: invalid value encountered in divide
  c /= stddev[:, None]

[2024-11-26T16:00:16.458+0000] {warnings.py:109} WARNING - /home/***/.local/lib/python3.8/site-packages/numpy/lib/function_base.py:2855: RuntimeWarning: invalid value encountered in divide
  c /= stddev[None, :]

[2024-11-26T16:00:16.463+0000] {warnings.py:109} WARNING - /home/***/.local/lib/python3.8/site-packages/numpy/lib/function_base.py:2854: RuntimeWarning: invalid value encountered in divide
  c /= stddev[:, None]

[2024-11-26T16:00:16.463+0000] {warnings.py:109} WARNING - /home/***/.local/lib/python3.8/site-packages/numpy/lib/function_base.py:2855: RuntimeWarning: invalid value encountered in divide
  c /= stddev[None, :]

[2024-11-26T16:00:16.614+0000] {warnings.py:109} WARNING - /home/***/.local/lib/python3.8/site-packages/numpy/lib/function_base.py:2854: RuntimeWarning: invalid value encountered in divide
  c /= stddev[:, None]

[2024-11-26T16:00:16.615+0000] {warnings.py:109} WARNING - /home/***/.local/lib/python3.8/site-packages/numpy/lib/function_base.py:2855: RuntimeWarning: invalid value encountered in divide
  c /= stddev[None, :]

[2024-11-26T16:00:16.621+0000] {warnings.py:109} WARNING - /home/***/.local/lib/python3.8/site-packages/numpy/lib/function_base.py:2854: RuntimeWarning: invalid value encountered in divide
  c /= stddev[:, None]

[2024-11-26T16:00:16.622+0000] {warnings.py:109} WARNING - /home/***/.local/lib/python3.8/site-packages/numpy/lib/function_base.py:2855: RuntimeWarning: invalid value encountered in divide
  c /= stddev[None, :]

[2024-11-26T16:00:16.953+0000] {python.py:194} INFO - Done. Returned value was: None
[2024-11-26T16:00:16.968+0000] {taskinstance.py:1400} INFO - Marking task as SUCCESS. dag_id=drift_detection_dag, task_id=data_drift_detected, execution_date=20241126T155659, start_date=20241126T160016, end_date=20241126T160016
[2024-11-26T16:00:17.010+0000] {local_task_job_runner.py:228} INFO - Task exited with return code 0
[2024-11-26T16:00:17.060+0000] {taskinstance.py:2778} INFO - 1 downstream tasks scheduled from follow-on schedule check
