[2024-01-24 15:39:47,475] {taskinstance.py:1159} INFO - Dependencies all met for <TaskInstance: monitoring_dag.data_drift_detected manual__2024-01-24T15:36:36.433675+00:00 [queued]>
[2024-01-24 15:39:47,484] {taskinstance.py:1159} INFO - Dependencies all met for <TaskInstance: monitoring_dag.data_drift_detected manual__2024-01-24T15:36:36.433675+00:00 [queued]>
[2024-01-24 15:39:47,484] {taskinstance.py:1356} INFO - 
--------------------------------------------------------------------------------
[2024-01-24 15:39:47,484] {taskinstance.py:1357} INFO - Starting attempt 2 of 6
[2024-01-24 15:39:47,484] {taskinstance.py:1358} INFO - 
--------------------------------------------------------------------------------
[2024-01-24 15:39:47,494] {taskinstance.py:1377} INFO - Executing <Task(PythonOperator): data_drift_detected> on 2024-01-24 15:36:36.433675+00:00
[2024-01-24 15:39:47,500] {standard_task_runner.py:52} INFO - Started process 1347 to run task
[2024-01-24 15:39:47,503] {standard_task_runner.py:79} INFO - Running: ['***', 'tasks', 'run', 'monitoring_dag', 'data_drift_detected', 'manual__2024-01-24T15:36:36.433675+00:00', '--job-id', '64', '--raw', '--subdir', 'DAGS_FOLDER/monitoring-dag.py', '--cfg-path', '/tmp/tmpy43q02lw', '--error-file', '/tmp/tmprlthtfs2']
[2024-01-24 15:39:47,504] {standard_task_runner.py:80} INFO - Job 64: Subtask data_drift_detected
[2024-01-24 15:39:47,546] {task_command.py:370} INFO - Running <TaskInstance: monitoring_dag.data_drift_detected manual__2024-01-24T15:36:36.433675+00:00 [running]> on host 7aa566990013
[2024-01-24 15:39:47,600] {taskinstance.py:1571} INFO - Exporting the following env vars:
AIRFLOW_CTX_DAG_OWNER=***
AIRFLOW_CTX_DAG_ID=monitoring_dag
AIRFLOW_CTX_TASK_ID=data_drift_detected
AIRFLOW_CTX_EXECUTION_DATE=2024-01-24T15:36:36.433675+00:00
AIRFLOW_CTX_TRY_NUMBER=2
AIRFLOW_CTX_DAG_RUN_ID=manual__2024-01-24T15:36:36.433675+00:00
[2024-01-24 15:39:47,616] {taskinstance.py:1889} ERROR - Task failed with exception
Traceback (most recent call last):
  File "/home/airflow/.local/lib/python3.7/site-packages/airflow/operators/python.py", line 171, in execute
    return_value = self.execute_callable()
  File "/home/airflow/.local/lib/python3.7/site-packages/airflow/operators/python.py", line 189, in execute_callable
    return self.python_callable(*self.op_args, **self.op_kwargs)
  File "/opt/airflow/dags/monitoring-dag.py", line 83, in _data_drift_detected
    reference, data_logs = _load_files(data_logs_filename)
  File "/opt/airflow/dags/monitoring-dag.py", line 40, in _load_files
    data_logs = pd.read_csv(data_logs_filename)
  File "/home/airflow/.local/lib/python3.7/site-packages/pandas/util/_decorators.py", line 311, in wrapper
    return func(*args, **kwargs)
  File "/home/airflow/.local/lib/python3.7/site-packages/pandas/io/parsers/readers.py", line 586, in read_csv
    return _read(filepath_or_buffer, kwds)
  File "/home/airflow/.local/lib/python3.7/site-packages/pandas/io/parsers/readers.py", line 482, in _read
    parser = TextFileReader(filepath_or_buffer, **kwds)
  File "/home/airflow/.local/lib/python3.7/site-packages/pandas/io/parsers/readers.py", line 811, in __init__
    self._engine = self._make_engine(self.engine)
  File "/home/airflow/.local/lib/python3.7/site-packages/pandas/io/parsers/readers.py", line 1040, in _make_engine
    return mapping[engine](self.f, **self.options)  # type: ignore[call-arg]
  File "/home/airflow/.local/lib/python3.7/site-packages/pandas/io/parsers/c_parser_wrapper.py", line 51, in __init__
    self._open_handles(src, kwds)
  File "/home/airflow/.local/lib/python3.7/site-packages/pandas/io/parsers/base_parser.py", line 229, in _open_handles
    errors=kwds.get("encoding_errors", "strict"),
  File "/home/airflow/.local/lib/python3.7/site-packages/pandas/io/common.py", line 707, in get_handle
    newline="",
FileNotFoundError: [Errno 2] No such file or directory: './data/data-drift/week1.csv'
[2024-01-24 15:39:47,624] {taskinstance.py:1400} INFO - Marking task as UP_FOR_RETRY. dag_id=monitoring_dag, task_id=data_drift_detected, execution_date=20240124T153636, start_date=20240124T153947, end_date=20240124T153947
[2024-01-24 15:39:47,631] {standard_task_runner.py:97} ERROR - Failed to execute job 64 for task data_drift_detected ([Errno 2] No such file or directory: './data/data-drift/week1.csv'; 1347)
[2024-01-24 15:39:47,676] {local_task_job.py:156} INFO - Task exited with return code 1
[2024-01-24 15:39:47,725] {local_task_job.py:273} INFO - 0 downstream tasks scheduled from follow-on schedule check
