[2024-11-26T11:57:13.446+0000] {taskinstance.py:1159} INFO - Dependencies all met for dep_context=non-requeueable deps ti=<TaskInstance: drift_detection_dag.data_drift_detected manual__2024-11-26T11:56:54.645242+00:00 [queued]>
[2024-11-26T11:57:13.457+0000] {taskinstance.py:1159} INFO - Dependencies all met for dep_context=requeueable deps ti=<TaskInstance: drift_detection_dag.data_drift_detected manual__2024-11-26T11:56:54.645242+00:00 [queued]>
[2024-11-26T11:57:13.458+0000] {taskinstance.py:1361} INFO - Starting attempt 1 of 1
[2024-11-26T11:57:13.472+0000] {taskinstance.py:1382} INFO - Executing <Task(PythonOperator): data_drift_detected> on 2024-11-26 11:56:54.645242+00:00
[2024-11-26T11:57:13.481+0000] {standard_task_runner.py:57} INFO - Started process 704 to run task
[2024-11-26T11:57:13.484+0000] {standard_task_runner.py:84} INFO - Running: ['***', 'tasks', 'run', 'drift_detection_dag', 'data_drift_detected', 'manual__2024-11-26T11:56:54.645242+00:00', '--job-id', '68', '--raw', '--subdir', 'DAGS_FOLDER/drift-detection.py', '--cfg-path', '/tmp/tmpqsxvn21b']
[2024-11-26T11:57:13.488+0000] {standard_task_runner.py:85} INFO - Job 68: Subtask data_drift_detected
[2024-11-26T11:57:13.540+0000] {task_command.py:416} INFO - Running <TaskInstance: drift_detection_dag.data_drift_detected manual__2024-11-26T11:56:54.645242+00:00 [running]> on host 7f10b2294d44
[2024-11-26T11:57:13.651+0000] {taskinstance.py:1662} INFO - Exporting env vars: AIRFLOW_CTX_DAG_OWNER='***' AIRFLOW_CTX_DAG_ID='drift_detection_dag' AIRFLOW_CTX_TASK_ID='data_drift_detected' AIRFLOW_CTX_EXECUTION_DATE='2024-11-26T11:56:54.645242+00:00' AIRFLOW_CTX_TRY_NUMBER='1' AIRFLOW_CTX_DAG_RUN_ID='manual__2024-11-26T11:56:54.645242+00:00'
[2024-11-26T11:57:13.721+0000] {warnings.py:109} WARNING - /home/***/.local/lib/python3.8/site-packages/numpy/lib/function_base.py:2854: RuntimeWarning: invalid value encountered in divide
  c /= stddev[:, None]

[2024-11-26T11:57:13.722+0000] {warnings.py:109} WARNING - /home/***/.local/lib/python3.8/site-packages/numpy/lib/function_base.py:2855: RuntimeWarning: invalid value encountered in divide
  c /= stddev[None, :]

[2024-11-26T11:57:13.725+0000] {warnings.py:109} WARNING - /home/***/.local/lib/python3.8/site-packages/numpy/lib/function_base.py:2854: RuntimeWarning: invalid value encountered in divide
  c /= stddev[:, None]

[2024-11-26T11:57:13.726+0000] {warnings.py:109} WARNING - /home/***/.local/lib/python3.8/site-packages/numpy/lib/function_base.py:2855: RuntimeWarning: invalid value encountered in divide
  c /= stddev[None, :]

[2024-11-26T11:57:13.833+0000] {warnings.py:109} WARNING - /home/***/.local/lib/python3.8/site-packages/numpy/lib/function_base.py:2854: RuntimeWarning: invalid value encountered in divide
  c /= stddev[:, None]

[2024-11-26T11:57:13.834+0000] {warnings.py:109} WARNING - /home/***/.local/lib/python3.8/site-packages/numpy/lib/function_base.py:2855: RuntimeWarning: invalid value encountered in divide
  c /= stddev[None, :]

[2024-11-26T11:57:13.836+0000] {warnings.py:109} WARNING - /home/***/.local/lib/python3.8/site-packages/numpy/lib/function_base.py:2854: RuntimeWarning: invalid value encountered in divide
  c /= stddev[:, None]

[2024-11-26T11:57:13.837+0000] {warnings.py:109} WARNING - /home/***/.local/lib/python3.8/site-packages/numpy/lib/function_base.py:2855: RuntimeWarning: invalid value encountered in divide
  c /= stddev[None, :]

[2024-11-26T11:57:14.010+0000] {python.py:194} INFO - Done. Returned value was: None
[2024-11-26T11:57:14.021+0000] {taskinstance.py:1400} INFO - Marking task as SUCCESS. dag_id=drift_detection_dag, task_id=data_drift_detected, execution_date=20241126T115654, start_date=20241126T115713, end_date=20241126T115714
[2024-11-26T11:57:14.059+0000] {local_task_job_runner.py:228} INFO - Task exited with return code 0
[2024-11-26T11:57:14.095+0000] {taskinstance.py:2778} INFO - 1 downstream tasks scheduled from follow-on schedule check
