[2024-11-27T13:35:29.579+0000] {taskinstance.py:1159} INFO - Dependencies all met for dep_context=non-requeueable deps ti=<TaskInstance: drift_detection_dag.detect_data_drift manual__2024-11-27T13:35:13.424971+00:00 [queued]>
[2024-11-27T13:35:29.593+0000] {taskinstance.py:1159} INFO - Dependencies all met for dep_context=requeueable deps ti=<TaskInstance: drift_detection_dag.detect_data_drift manual__2024-11-27T13:35:13.424971+00:00 [queued]>
[2024-11-27T13:35:29.593+0000] {taskinstance.py:1361} INFO - Starting attempt 1 of 1
[2024-11-27T13:35:29.615+0000] {taskinstance.py:1382} INFO - Executing <Task(BranchPythonOperator): detect_data_drift> on 2024-11-27 13:35:13.424971+00:00
[2024-11-27T13:35:29.625+0000] {standard_task_runner.py:57} INFO - Started process 35541 to run task
[2024-11-27T13:35:29.631+0000] {standard_task_runner.py:84} INFO - Running: ['***', 'tasks', 'run', 'drift_detection_dag', 'detect_data_drift', 'manual__2024-11-27T13:35:13.424971+00:00', '--job-id', '37', '--raw', '--subdir', 'DAGS_FOLDER/drift-detection.py', '--cfg-path', '/tmp/tmpv_8t0z48']
[2024-11-27T13:35:29.638+0000] {standard_task_runner.py:85} INFO - Job 37: Subtask detect_data_drift
[2024-11-27T13:35:29.705+0000] {task_command.py:416} INFO - Running <TaskInstance: drift_detection_dag.detect_data_drift manual__2024-11-27T13:35:13.424971+00:00 [running]> on host 88ce0f125f41
[2024-11-27T13:35:29.799+0000] {taskinstance.py:1662} INFO - Exporting env vars: AIRFLOW_CTX_DAG_OWNER='***' AIRFLOW_CTX_DAG_ID='drift_detection_dag' AIRFLOW_CTX_TASK_ID='detect_data_drift' AIRFLOW_CTX_EXECUTION_DATE='2024-11-27T13:35:13.424971+00:00' AIRFLOW_CTX_TRY_NUMBER='1' AIRFLOW_CTX_DAG_RUN_ID='manual__2024-11-27T13:35:13.424971+00:00'
[2024-11-27T13:35:29.881+0000] {warnings.py:109} WARNING - /home/***/.local/lib/python3.8/site-packages/numpy/lib/function_base.py:2854: RuntimeWarning: invalid value encountered in divide
  c /= stddev[:, None]

[2024-11-27T13:35:29.882+0000] {warnings.py:109} WARNING - /home/***/.local/lib/python3.8/site-packages/numpy/lib/function_base.py:2855: RuntimeWarning: invalid value encountered in divide
  c /= stddev[None, :]

[2024-11-27T13:35:29.887+0000] {warnings.py:109} WARNING - /home/***/.local/lib/python3.8/site-packages/numpy/lib/function_base.py:2854: RuntimeWarning: invalid value encountered in divide
  c /= stddev[:, None]

[2024-11-27T13:35:29.888+0000] {warnings.py:109} WARNING - /home/***/.local/lib/python3.8/site-packages/numpy/lib/function_base.py:2855: RuntimeWarning: invalid value encountered in divide
  c /= stddev[None, :]

[2024-11-27T13:35:30.003+0000] {warnings.py:109} WARNING - /home/***/.local/lib/python3.8/site-packages/numpy/lib/function_base.py:2854: RuntimeWarning: invalid value encountered in divide
  c /= stddev[:, None]

[2024-11-27T13:35:30.004+0000] {warnings.py:109} WARNING - /home/***/.local/lib/python3.8/site-packages/numpy/lib/function_base.py:2855: RuntimeWarning: invalid value encountered in divide
  c /= stddev[None, :]

[2024-11-27T13:35:30.008+0000] {warnings.py:109} WARNING - /home/***/.local/lib/python3.8/site-packages/numpy/lib/function_base.py:2854: RuntimeWarning: invalid value encountered in divide
  c /= stddev[:, None]

[2024-11-27T13:35:30.009+0000] {warnings.py:109} WARNING - /home/***/.local/lib/python3.8/site-packages/numpy/lib/function_base.py:2855: RuntimeWarning: invalid value encountered in divide
  c /= stddev[None, :]

[2024-11-27T13:35:30.113+0000] {python.py:194} INFO - Done. Returned value was: data_drift_detected
[2024-11-27T13:35:30.114+0000] {python.py:227} INFO - Branch callable return data_drift_detected
[2024-11-27T13:35:30.114+0000] {skipmixin.py:173} INFO - Following branch data_drift_detected
[2024-11-27T13:35:30.135+0000] {skipmixin.py:239} INFO - Skipping tasks [('no_data_drift_detected', -1)]
[2024-11-27T13:35:30.186+0000] {taskinstance.py:1400} INFO - Marking task as SUCCESS. dag_id=drift_detection_dag, task_id=detect_data_drift, execution_date=20241127T133513, start_date=20241127T133529, end_date=20241127T133530
[2024-11-27T13:35:30.245+0000] {local_task_job_runner.py:228} INFO - Task exited with return code 0
[2024-11-27T13:35:30.289+0000] {taskinstance.py:2778} INFO - 1 downstream tasks scheduled from follow-on schedule check
