[2024-11-26T00:20:32.385+0000] {taskinstance.py:1159} INFO - Dependencies all met for dep_context=non-requeueable deps ti=<TaskInstance: drift_detection_dag.detect_data_drift manual__2024-11-26T00:20:20.002617+00:00 [queued]>
[2024-11-26T00:20:32.398+0000] {taskinstance.py:1159} INFO - Dependencies all met for dep_context=requeueable deps ti=<TaskInstance: drift_detection_dag.detect_data_drift manual__2024-11-26T00:20:20.002617+00:00 [queued]>
[2024-11-26T00:20:32.399+0000] {taskinstance.py:1361} INFO - Starting attempt 1 of 1
[2024-11-26T00:20:32.415+0000] {taskinstance.py:1382} INFO - Executing <Task(BranchPythonOperator): detect_data_drift> on 2024-11-26 00:20:20.002617+00:00
[2024-11-26T00:20:32.424+0000] {standard_task_runner.py:57} INFO - Started process 5092 to run task
[2024-11-26T00:20:32.428+0000] {standard_task_runner.py:84} INFO - Running: ['***', 'tasks', 'run', 'drift_detection_dag', 'detect_data_drift', 'manual__2024-11-26T00:20:20.002617+00:00', '--job-id', '36', '--raw', '--subdir', 'DAGS_FOLDER/drift-detection.py', '--cfg-path', '/tmp/tmp_tkv8bau']
[2024-11-26T00:20:32.431+0000] {standard_task_runner.py:85} INFO - Job 36: Subtask detect_data_drift
[2024-11-26T00:20:32.484+0000] {task_command.py:416} INFO - Running <TaskInstance: drift_detection_dag.detect_data_drift manual__2024-11-26T00:20:20.002617+00:00 [running]> on host 7f10b2294d44
[2024-11-26T00:20:32.562+0000] {taskinstance.py:1662} INFO - Exporting env vars: AIRFLOW_CTX_DAG_OWNER='***' AIRFLOW_CTX_DAG_ID='drift_detection_dag' AIRFLOW_CTX_TASK_ID='detect_data_drift' AIRFLOW_CTX_EXECUTION_DATE='2024-11-26T00:20:20.002617+00:00' AIRFLOW_CTX_TRY_NUMBER='1' AIRFLOW_CTX_DAG_RUN_ID='manual__2024-11-26T00:20:20.002617+00:00'
[2024-11-26T00:20:32.687+0000] {warnings.py:109} WARNING - /home/***/.local/lib/python3.8/site-packages/numpy/lib/function_base.py:2854: RuntimeWarning: invalid value encountered in divide
  c /= stddev[:, None]

[2024-11-26T00:20:32.688+0000] {warnings.py:109} WARNING - /home/***/.local/lib/python3.8/site-packages/numpy/lib/function_base.py:2855: RuntimeWarning: invalid value encountered in divide
  c /= stddev[None, :]

[2024-11-26T00:20:32.691+0000] {warnings.py:109} WARNING - /home/***/.local/lib/python3.8/site-packages/numpy/lib/function_base.py:2854: RuntimeWarning: invalid value encountered in divide
  c /= stddev[:, None]

[2024-11-26T00:20:32.692+0000] {warnings.py:109} WARNING - /home/***/.local/lib/python3.8/site-packages/numpy/lib/function_base.py:2855: RuntimeWarning: invalid value encountered in divide
  c /= stddev[None, :]

[2024-11-26T00:20:32.784+0000] {warnings.py:109} WARNING - /home/***/.local/lib/python3.8/site-packages/numpy/lib/function_base.py:2854: RuntimeWarning: invalid value encountered in divide
  c /= stddev[:, None]

[2024-11-26T00:20:32.785+0000] {warnings.py:109} WARNING - /home/***/.local/lib/python3.8/site-packages/numpy/lib/function_base.py:2855: RuntimeWarning: invalid value encountered in divide
  c /= stddev[None, :]

[2024-11-26T00:20:32.789+0000] {warnings.py:109} WARNING - /home/***/.local/lib/python3.8/site-packages/numpy/lib/function_base.py:2854: RuntimeWarning: invalid value encountered in divide
  c /= stddev[:, None]

[2024-11-26T00:20:32.790+0000] {warnings.py:109} WARNING - /home/***/.local/lib/python3.8/site-packages/numpy/lib/function_base.py:2855: RuntimeWarning: invalid value encountered in divide
  c /= stddev[None, :]

[2024-11-26T00:20:32.865+0000] {python.py:194} INFO - Done. Returned value was: no_data_drift_detected
[2024-11-26T00:20:32.866+0000] {python.py:227} INFO - Branch callable return no_data_drift_detected
[2024-11-26T00:20:32.867+0000] {skipmixin.py:173} INFO - Following branch no_data_drift_detected
[2024-11-26T00:20:32.885+0000] {skipmixin.py:239} INFO - Skipping tasks [('data_drift_detected', -1)]
[2024-11-26T00:20:32.934+0000] {taskinstance.py:1400} INFO - Marking task as SUCCESS. dag_id=drift_detection_dag, task_id=detect_data_drift, execution_date=20241126T002020, start_date=20241126T002032, end_date=20241126T002032
[2024-11-26T00:20:33.002+0000] {local_task_job_runner.py:228} INFO - Task exited with return code 0
[2024-11-26T00:20:33.045+0000] {taskinstance.py:2778} INFO - 0 downstream tasks scheduled from follow-on schedule check
