[2024-11-26T19:01:19.848+0000] {taskinstance.py:1159} INFO - Dependencies all met for dep_context=non-requeueable deps ti=<TaskInstance: drift_detection_dag.detect_data_drift manual__2024-11-26T19:01:07.445148+00:00 [queued]>
[2024-11-26T19:01:19.859+0000] {taskinstance.py:1159} INFO - Dependencies all met for dep_context=requeueable deps ti=<TaskInstance: drift_detection_dag.detect_data_drift manual__2024-11-26T19:01:07.445148+00:00 [queued]>
[2024-11-26T19:01:19.860+0000] {taskinstance.py:1361} INFO - Starting attempt 1 of 1
[2024-11-26T19:01:19.877+0000] {taskinstance.py:1382} INFO - Executing <Task(BranchPythonOperator): detect_data_drift> on 2024-11-26 19:01:07.445148+00:00
[2024-11-26T19:01:19.886+0000] {standard_task_runner.py:57} INFO - Started process 1081 to run task
[2024-11-26T19:01:19.890+0000] {standard_task_runner.py:84} INFO - Running: ['***', 'tasks', 'run', 'drift_detection_dag', 'detect_data_drift', 'manual__2024-11-26T19:01:07.445148+00:00', '--job-id', '19', '--raw', '--subdir', 'DAGS_FOLDER/drift-detection.py', '--cfg-path', '/tmp/tmpasq7zadp']
[2024-11-26T19:01:19.893+0000] {standard_task_runner.py:85} INFO - Job 19: Subtask detect_data_drift
[2024-11-26T19:01:19.941+0000] {task_command.py:416} INFO - Running <TaskInstance: drift_detection_dag.detect_data_drift manual__2024-11-26T19:01:07.445148+00:00 [running]> on host 88ce0f125f41
[2024-11-26T19:01:20.029+0000] {taskinstance.py:1662} INFO - Exporting env vars: AIRFLOW_CTX_DAG_OWNER='***' AIRFLOW_CTX_DAG_ID='drift_detection_dag' AIRFLOW_CTX_TASK_ID='detect_data_drift' AIRFLOW_CTX_EXECUTION_DATE='2024-11-26T19:01:07.445148+00:00' AIRFLOW_CTX_TRY_NUMBER='1' AIRFLOW_CTX_DAG_RUN_ID='manual__2024-11-26T19:01:07.445148+00:00'
[2024-11-26T19:01:20.087+0000] {warnings.py:109} WARNING - /home/***/.local/lib/python3.8/site-packages/numpy/lib/function_base.py:2854: RuntimeWarning: invalid value encountered in divide
  c /= stddev[:, None]

[2024-11-26T19:01:20.088+0000] {warnings.py:109} WARNING - /home/***/.local/lib/python3.8/site-packages/numpy/lib/function_base.py:2855: RuntimeWarning: invalid value encountered in divide
  c /= stddev[None, :]

[2024-11-26T19:01:20.091+0000] {warnings.py:109} WARNING - /home/***/.local/lib/python3.8/site-packages/numpy/lib/function_base.py:2854: RuntimeWarning: invalid value encountered in divide
  c /= stddev[:, None]

[2024-11-26T19:01:20.092+0000] {warnings.py:109} WARNING - /home/***/.local/lib/python3.8/site-packages/numpy/lib/function_base.py:2855: RuntimeWarning: invalid value encountered in divide
  c /= stddev[None, :]

[2024-11-26T19:01:20.170+0000] {warnings.py:109} WARNING - /home/***/.local/lib/python3.8/site-packages/numpy/lib/function_base.py:2854: RuntimeWarning: invalid value encountered in divide
  c /= stddev[:, None]

[2024-11-26T19:01:20.171+0000] {warnings.py:109} WARNING - /home/***/.local/lib/python3.8/site-packages/numpy/lib/function_base.py:2855: RuntimeWarning: invalid value encountered in divide
  c /= stddev[None, :]

[2024-11-26T19:01:20.175+0000] {warnings.py:109} WARNING - /home/***/.local/lib/python3.8/site-packages/numpy/lib/function_base.py:2854: RuntimeWarning: invalid value encountered in divide
  c /= stddev[:, None]

[2024-11-26T19:01:20.176+0000] {warnings.py:109} WARNING - /home/***/.local/lib/python3.8/site-packages/numpy/lib/function_base.py:2855: RuntimeWarning: invalid value encountered in divide
  c /= stddev[None, :]

[2024-11-26T19:01:20.272+0000] {python.py:194} INFO - Done. Returned value was: no_data_drift_detected
[2024-11-26T19:01:20.272+0000] {python.py:227} INFO - Branch callable return no_data_drift_detected
[2024-11-26T19:01:20.273+0000] {skipmixin.py:173} INFO - Following branch no_data_drift_detected
[2024-11-26T19:01:20.287+0000] {skipmixin.py:239} INFO - Skipping tasks [('data_drift_detected', -1)]
[2024-11-26T19:01:20.330+0000] {taskinstance.py:1400} INFO - Marking task as SUCCESS. dag_id=drift_detection_dag, task_id=detect_data_drift, execution_date=20241126T190107, start_date=20241126T190119, end_date=20241126T190120
[2024-11-26T19:01:20.384+0000] {local_task_job_runner.py:228} INFO - Task exited with return code 0
[2024-11-26T19:01:20.415+0000] {taskinstance.py:2778} INFO - 0 downstream tasks scheduled from follow-on schedule check
