[2024-11-26T16:00:07.987+0000] {taskinstance.py:1159} INFO - Dependencies all met for dep_context=non-requeueable deps ti=<TaskInstance: drift_detection_dag.detect_data_drift manual__2024-11-26T15:56:59.323643+00:00 [queued]>
[2024-11-26T16:00:08.004+0000] {taskinstance.py:1159} INFO - Dependencies all met for dep_context=requeueable deps ti=<TaskInstance: drift_detection_dag.detect_data_drift manual__2024-11-26T15:56:59.323643+00:00 [queued]>
[2024-11-26T16:00:08.005+0000] {taskinstance.py:1361} INFO - Starting attempt 2 of 2
[2024-11-26T16:00:08.030+0000] {taskinstance.py:1382} INFO - Executing <Task(BranchPythonOperator): detect_data_drift> on 2024-11-26 15:56:59.323643+00:00
[2024-11-26T16:00:08.042+0000] {standard_task_runner.py:57} INFO - Started process 467 to run task
[2024-11-26T16:00:08.048+0000] {standard_task_runner.py:84} INFO - Running: ['***', 'tasks', 'run', 'drift_detection_dag', 'detect_data_drift', 'manual__2024-11-26T15:56:59.323643+00:00', '--job-id', '13', '--raw', '--subdir', 'DAGS_FOLDER/drift-detection.py', '--cfg-path', '/tmp/tmpu2rq9mne']
[2024-11-26T16:00:08.053+0000] {standard_task_runner.py:85} INFO - Job 13: Subtask detect_data_drift
[2024-11-26T16:00:08.129+0000] {task_command.py:416} INFO - Running <TaskInstance: drift_detection_dag.detect_data_drift manual__2024-11-26T15:56:59.323643+00:00 [running]> on host e76aaec22df7
[2024-11-26T16:00:08.244+0000] {taskinstance.py:1662} INFO - Exporting env vars: AIRFLOW_CTX_DAG_OWNER='***' AIRFLOW_CTX_DAG_ID='drift_detection_dag' AIRFLOW_CTX_TASK_ID='detect_data_drift' AIRFLOW_CTX_EXECUTION_DATE='2024-11-26T15:56:59.323643+00:00' AIRFLOW_CTX_TRY_NUMBER='2' AIRFLOW_CTX_DAG_RUN_ID='manual__2024-11-26T15:56:59.323643+00:00'
[2024-11-26T16:00:08.337+0000] {warnings.py:109} WARNING - /home/***/.local/lib/python3.8/site-packages/numpy/lib/function_base.py:2854: RuntimeWarning: invalid value encountered in divide
  c /= stddev[:, None]

[2024-11-26T16:00:08.338+0000] {warnings.py:109} WARNING - /home/***/.local/lib/python3.8/site-packages/numpy/lib/function_base.py:2855: RuntimeWarning: invalid value encountered in divide
  c /= stddev[None, :]

[2024-11-26T16:00:08.342+0000] {warnings.py:109} WARNING - /home/***/.local/lib/python3.8/site-packages/numpy/lib/function_base.py:2854: RuntimeWarning: invalid value encountered in divide
  c /= stddev[:, None]

[2024-11-26T16:00:08.343+0000] {warnings.py:109} WARNING - /home/***/.local/lib/python3.8/site-packages/numpy/lib/function_base.py:2855: RuntimeWarning: invalid value encountered in divide
  c /= stddev[None, :]

[2024-11-26T16:00:08.537+0000] {warnings.py:109} WARNING - /home/***/.local/lib/python3.8/site-packages/numpy/lib/function_base.py:2854: RuntimeWarning: invalid value encountered in divide
  c /= stddev[:, None]

[2024-11-26T16:00:08.540+0000] {warnings.py:109} WARNING - /home/***/.local/lib/python3.8/site-packages/numpy/lib/function_base.py:2855: RuntimeWarning: invalid value encountered in divide
  c /= stddev[None, :]

[2024-11-26T16:00:08.547+0000] {warnings.py:109} WARNING - /home/***/.local/lib/python3.8/site-packages/numpy/lib/function_base.py:2854: RuntimeWarning: invalid value encountered in divide
  c /= stddev[:, None]

[2024-11-26T16:00:08.548+0000] {warnings.py:109} WARNING - /home/***/.local/lib/python3.8/site-packages/numpy/lib/function_base.py:2855: RuntimeWarning: invalid value encountered in divide
  c /= stddev[None, :]

[2024-11-26T16:00:08.736+0000] {python.py:194} INFO - Done. Returned value was: data_drift_detected
[2024-11-26T16:00:08.736+0000] {python.py:227} INFO - Branch callable return data_drift_detected
[2024-11-26T16:00:08.737+0000] {skipmixin.py:173} INFO - Following branch data_drift_detected
[2024-11-26T16:00:08.770+0000] {skipmixin.py:239} INFO - Skipping tasks [('no_data_drift_detected', -1)]
[2024-11-26T16:00:08.842+0000] {taskinstance.py:1400} INFO - Marking task as SUCCESS. dag_id=drift_detection_dag, task_id=detect_data_drift, execution_date=20241126T155659, start_date=20241126T160007, end_date=20241126T160008
[2024-11-26T16:00:08.905+0000] {local_task_job_runner.py:228} INFO - Task exited with return code 0
[2024-11-26T16:00:08.953+0000] {taskinstance.py:2778} INFO - 1 downstream tasks scheduled from follow-on schedule check
