[2024-11-26T12:34:38.672+0000] {taskinstance.py:1159} INFO - Dependencies all met for dep_context=non-requeueable deps ti=<TaskInstance: drift_detection_dag.send_email scheduled__2024-11-24T16:00:00+00:00 [queued]>
[2024-11-26T12:34:38.684+0000] {taskinstance.py:1159} INFO - Dependencies all met for dep_context=requeueable deps ti=<TaskInstance: drift_detection_dag.send_email scheduled__2024-11-24T16:00:00+00:00 [queued]>
[2024-11-26T12:34:38.685+0000] {taskinstance.py:1361} INFO - Starting attempt 1 of 1
[2024-11-26T12:34:38.702+0000] {taskinstance.py:1382} INFO - Executing <Task(EmailOperator): send_email> on 2024-11-24 16:00:00+00:00
[2024-11-26T12:34:38.716+0000] {standard_task_runner.py:57} INFO - Started process 260 to run task
[2024-11-26T12:34:38.721+0000] {standard_task_runner.py:84} INFO - Running: ['***', 'tasks', 'run', 'drift_detection_dag', 'send_email', 'scheduled__2024-11-24T16:00:00+00:00', '--job-id', '9', '--raw', '--subdir', 'DAGS_FOLDER/drift-detection.py', '--cfg-path', '/tmp/tmpzvsz38ky']
[2024-11-26T12:34:38.724+0000] {standard_task_runner.py:85} INFO - Job 9: Subtask send_email
[2024-11-26T12:34:38.790+0000] {task_command.py:416} INFO - Running <TaskInstance: drift_detection_dag.send_email scheduled__2024-11-24T16:00:00+00:00 [running]> on host c359b096823c
[2024-11-26T12:34:38.844+0000] {abstractoperator.py:709} ERROR - Exception rendering Jinja template for task 'send_email', field 'files'. Template: ['/opt/***/data/data_drift_dashboard_report.html']
Traceback (most recent call last):
  File "/home/airflow/.local/lib/python3.8/site-packages/airflow/models/abstractoperator.py", line 701, in _do_render_template_fields
    rendered_content = self.render_template(
  File "/home/airflow/.local/lib/python3.8/site-packages/airflow/template/templater.py", line 165, in render_template
    return [self.render_template(element, context, jinja_env, oids) for element in value]
  File "/home/airflow/.local/lib/python3.8/site-packages/airflow/template/templater.py", line 165, in <listcomp>
    return [self.render_template(element, context, jinja_env, oids) for element in value]
  File "/home/airflow/.local/lib/python3.8/site-packages/airflow/template/templater.py", line 152, in render_template
    template = jinja_env.get_template(value)
  File "/home/airflow/.local/lib/python3.8/site-packages/jinja2/environment.py", line 1010, in get_template
    return self._load_template(name, globals)
  File "/home/airflow/.local/lib/python3.8/site-packages/jinja2/environment.py", line 969, in _load_template
    template = self.loader.load(self, name, self.make_globals(globals))
  File "/home/airflow/.local/lib/python3.8/site-packages/jinja2/loaders.py", line 126, in load
    source, filename, uptodate = self.get_source(environment, name)
  File "/home/airflow/.local/lib/python3.8/site-packages/jinja2/loaders.py", line 218, in get_source
    raise TemplateNotFound(template)
jinja2.exceptions.TemplateNotFound: /opt/airflow/data/data_drift_dashboard_report.html
[2024-11-26T12:34:38.847+0000] {taskinstance.py:1937} ERROR - Task failed with exception
Traceback (most recent call last):
  File "/home/airflow/.local/lib/python3.8/site-packages/airflow/models/taskinstance.py", line 1518, in _run_raw_task
    self._execute_task_with_callbacks(context, test_mode, session=session)
  File "/home/airflow/.local/lib/python3.8/site-packages/airflow/models/taskinstance.py", line 1647, in _execute_task_with_callbacks
    task_orig = self.render_templates(context=context)
  File "/home/airflow/.local/lib/python3.8/site-packages/airflow/models/taskinstance.py", line 2285, in render_templates
    original_task.render_template_fields(context)
  File "/home/airflow/.local/lib/python3.8/site-packages/airflow/models/baseoperator.py", line 1243, in render_template_fields
    self._do_render_template_fields(self, self.template_fields, context, jinja_env, set())
  File "/home/airflow/.local/lib/python3.8/site-packages/airflow/utils/session.py", line 79, in wrapper
    return func(*args, session=session, **kwargs)
  File "/home/airflow/.local/lib/python3.8/site-packages/airflow/models/abstractoperator.py", line 701, in _do_render_template_fields
    rendered_content = self.render_template(
  File "/home/airflow/.local/lib/python3.8/site-packages/airflow/template/templater.py", line 165, in render_template
    return [self.render_template(element, context, jinja_env, oids) for element in value]
  File "/home/airflow/.local/lib/python3.8/site-packages/airflow/template/templater.py", line 165, in <listcomp>
    return [self.render_template(element, context, jinja_env, oids) for element in value]
  File "/home/airflow/.local/lib/python3.8/site-packages/airflow/template/templater.py", line 152, in render_template
    template = jinja_env.get_template(value)
  File "/home/airflow/.local/lib/python3.8/site-packages/jinja2/environment.py", line 1010, in get_template
    return self._load_template(name, globals)
  File "/home/airflow/.local/lib/python3.8/site-packages/jinja2/environment.py", line 969, in _load_template
    template = self.loader.load(self, name, self.make_globals(globals))
  File "/home/airflow/.local/lib/python3.8/site-packages/jinja2/loaders.py", line 126, in load
    source, filename, uptodate = self.get_source(environment, name)
  File "/home/airflow/.local/lib/python3.8/site-packages/jinja2/loaders.py", line 218, in get_source
    raise TemplateNotFound(template)
jinja2.exceptions.TemplateNotFound: /opt/airflow/data/data_drift_dashboard_report.html
[2024-11-26T12:34:38.860+0000] {taskinstance.py:1400} INFO - Marking task as FAILED. dag_id=drift_detection_dag, task_id=send_email, execution_date=20241124T160000, start_date=20241126T123438, end_date=20241126T123438
[2024-11-26T12:34:38.876+0000] {standard_task_runner.py:104} ERROR - Failed to execute job 9 for task send_email (/opt/airflow/data/data_drift_dashboard_report.html; 260)
[2024-11-26T12:34:38.932+0000] {local_task_job_runner.py:228} INFO - Task exited with return code 1
[2024-11-26T12:34:38.967+0000] {taskinstance.py:2778} INFO - 0 downstream tasks scheduled from follow-on schedule check
[2024-11-26T13:40:32.321+0000] {taskinstance.py:1159} INFO - Dependencies all met for dep_context=non-requeueable deps ti=<TaskInstance: drift_detection_dag.send_email scheduled__2024-11-24T16:00:00+00:00 [queued]>
[2024-11-26T13:40:32.332+0000] {taskinstance.py:1159} INFO - Dependencies all met for dep_context=requeueable deps ti=<TaskInstance: drift_detection_dag.send_email scheduled__2024-11-24T16:00:00+00:00 [queued]>
[2024-11-26T13:40:32.332+0000] {taskinstance.py:1361} INFO - Starting attempt 1 of 1
[2024-11-26T13:40:32.349+0000] {taskinstance.py:1382} INFO - Executing <Task(EmailOperator): send_email> on 2024-11-24 16:00:00+00:00
[2024-11-26T13:40:32.357+0000] {standard_task_runner.py:57} INFO - Started process 367 to run task
[2024-11-26T13:40:32.361+0000] {standard_task_runner.py:84} INFO - Running: ['***', 'tasks', 'run', 'drift_detection_dag', 'send_email', 'scheduled__2024-11-24T16:00:00+00:00', '--job-id', '10', '--raw', '--subdir', 'DAGS_FOLDER/drift-detection.py', '--cfg-path', '/tmp/tmpw8ohz8g1']
[2024-11-26T13:40:32.365+0000] {standard_task_runner.py:85} INFO - Job 10: Subtask send_email
[2024-11-26T13:40:32.415+0000] {task_command.py:416} INFO - Running <TaskInstance: drift_detection_dag.send_email scheduled__2024-11-24T16:00:00+00:00 [running]> on host 8e7793c99557
[2024-11-26T13:40:32.489+0000] {taskinstance.py:1662} INFO - Exporting env vars: AIRFLOW_CTX_DAG_OWNER='***' AIRFLOW_CTX_DAG_ID='drift_detection_dag' AIRFLOW_CTX_TASK_ID='send_email' AIRFLOW_CTX_EXECUTION_DATE='2024-11-24T16:00:00+00:00' AIRFLOW_CTX_TRY_NUMBER='1' AIRFLOW_CTX_DAG_RUN_ID='scheduled__2024-11-24T16:00:00+00:00'
[2024-11-26T13:40:32.500+0000] {warnings.py:109} WARNING - /home/***/.local/lib/python3.8/site-packages/***/utils/email.py:154: RemovedInAirflow3Warning: Fetching SMTP credentials from configuration variables will be deprecated in a future release. Please set credentials using a connection instead.
  send_mime_email(e_from=mail_from, e_to=recipients, mime_msg=msg, conn_id=conn_id, dryrun=dryrun)

[2024-11-26T13:40:32.500+0000] {configuration.py:1050} WARNING - section/key [smtp/smtp_user] not found in config
[2024-11-26T13:40:32.501+0000] {email.py:270} INFO - Email alerting: attempt 1
[2024-11-26T13:40:32.502+0000] {taskinstance.py:1937} ERROR - Task failed with exception
Traceback (most recent call last):
  File "/home/airflow/.local/lib/python3.8/site-packages/airflow/operators/email.py", line 77, in execute
    send_email(
  File "/home/airflow/.local/lib/python3.8/site-packages/airflow/utils/email.py", line 80, in send_email
    return backend(
  File "/home/airflow/.local/lib/python3.8/site-packages/airflow/utils/email.py", line 154, in send_email_smtp
    send_mime_email(e_from=mail_from, e_to=recipients, mime_msg=msg, conn_id=conn_id, dryrun=dryrun)
  File "/home/airflow/.local/lib/python3.8/site-packages/airflow/utils/email.py", line 272, in send_mime_email
    smtp_conn = _get_smtp_connection(smtp_host, smtp_port, smtp_timeout, smtp_ssl)
  File "/home/airflow/.local/lib/python3.8/site-packages/airflow/utils/email.py", line 316, in _get_smtp_connection
    return smtplib.SMTP(host=host, port=port, timeout=timeout)
  File "/usr/local/lib/python3.8/smtplib.py", line 255, in __init__
    (code, msg) = self.connect(host, port)
  File "/usr/local/lib/python3.8/smtplib.py", line 339, in connect
    self.sock = self._get_socket(host, port, self.timeout)
  File "/usr/local/lib/python3.8/smtplib.py", line 310, in _get_socket
    return socket.create_connection((host, port), timeout,
  File "/usr/local/lib/python3.8/socket.py", line 808, in create_connection
    raise err
  File "/usr/local/lib/python3.8/socket.py", line 796, in create_connection
    sock.connect(sa)
ConnectionRefusedError: [Errno 111] Connection refused
[2024-11-26T13:40:32.510+0000] {taskinstance.py:1400} INFO - Marking task as FAILED. dag_id=drift_detection_dag, task_id=send_email, execution_date=20241124T160000, start_date=20241126T134032, end_date=20241126T134032
[2024-11-26T13:40:32.521+0000] {standard_task_runner.py:104} ERROR - Failed to execute job 10 for task send_email ([Errno 111] Connection refused; 367)
[2024-11-26T13:40:32.574+0000] {local_task_job_runner.py:228} INFO - Task exited with return code 1
[2024-11-26T13:40:32.600+0000] {taskinstance.py:2778} INFO - 0 downstream tasks scheduled from follow-on schedule check
[2024-11-26T15:57:30.923+0000] {taskinstance.py:1159} INFO - Dependencies all met for dep_context=non-requeueable deps ti=<TaskInstance: drift_detection_dag.send_email scheduled__2024-11-24T16:00:00+00:00 [queued]>
[2024-11-26T15:57:30.935+0000] {taskinstance.py:1159} INFO - Dependencies all met for dep_context=requeueable deps ti=<TaskInstance: drift_detection_dag.send_email scheduled__2024-11-24T16:00:00+00:00 [queued]>
[2024-11-26T15:57:30.936+0000] {taskinstance.py:1361} INFO - Starting attempt 1 of 1
[2024-11-26T15:57:30.953+0000] {taskinstance.py:1382} INFO - Executing <Task(EmailOperator): send_email> on 2024-11-24 16:00:00+00:00
[2024-11-26T15:57:30.963+0000] {standard_task_runner.py:57} INFO - Started process 328 to run task
[2024-11-26T15:57:30.967+0000] {standard_task_runner.py:84} INFO - Running: ['***', 'tasks', 'run', 'drift_detection_dag', 'send_email', 'scheduled__2024-11-24T16:00:00+00:00', '--job-id', '9', '--raw', '--subdir', 'DAGS_FOLDER/drift-detection.py', '--cfg-path', '/tmp/tmpn7vg7ctp']
[2024-11-26T15:57:30.970+0000] {standard_task_runner.py:85} INFO - Job 9: Subtask send_email
[2024-11-26T15:57:31.033+0000] {task_command.py:416} INFO - Running <TaskInstance: drift_detection_dag.send_email scheduled__2024-11-24T16:00:00+00:00 [running]> on host e76aaec22df7
[2024-11-26T15:57:31.123+0000] {taskinstance.py:1662} INFO - Exporting env vars: AIRFLOW_CTX_DAG_OWNER='***' AIRFLOW_CTX_DAG_ID='drift_detection_dag' AIRFLOW_CTX_TASK_ID='send_email' AIRFLOW_CTX_EXECUTION_DATE='2024-11-24T16:00:00+00:00' AIRFLOW_CTX_TRY_NUMBER='1' AIRFLOW_CTX_DAG_RUN_ID='scheduled__2024-11-24T16:00:00+00:00'
[2024-11-26T15:57:31.136+0000] {warnings.py:109} WARNING - /home/***/.local/lib/python3.8/site-packages/***/utils/email.py:154: RemovedInAirflow3Warning: Fetching SMTP credentials from configuration variables will be deprecated in a future release. Please set credentials using a connection instead.
  send_mime_email(e_from=mail_from, e_to=recipients, mime_msg=msg, conn_id=conn_id, dryrun=dryrun)

[2024-11-26T15:57:31.137+0000] {configuration.py:1050} WARNING - section/key [smtp/smtp_user] not found in config
[2024-11-26T15:57:31.137+0000] {email.py:270} INFO - Email alerting: attempt 1
[2024-11-26T15:57:31.138+0000] {taskinstance.py:1937} ERROR - Task failed with exception
Traceback (most recent call last):
  File "/home/airflow/.local/lib/python3.8/site-packages/airflow/operators/email.py", line 77, in execute
    send_email(
  File "/home/airflow/.local/lib/python3.8/site-packages/airflow/utils/email.py", line 80, in send_email
    return backend(
  File "/home/airflow/.local/lib/python3.8/site-packages/airflow/utils/email.py", line 154, in send_email_smtp
    send_mime_email(e_from=mail_from, e_to=recipients, mime_msg=msg, conn_id=conn_id, dryrun=dryrun)
  File "/home/airflow/.local/lib/python3.8/site-packages/airflow/utils/email.py", line 272, in send_mime_email
    smtp_conn = _get_smtp_connection(smtp_host, smtp_port, smtp_timeout, smtp_ssl)
  File "/home/airflow/.local/lib/python3.8/site-packages/airflow/utils/email.py", line 316, in _get_smtp_connection
    return smtplib.SMTP(host=host, port=port, timeout=timeout)
  File "/usr/local/lib/python3.8/smtplib.py", line 255, in __init__
    (code, msg) = self.connect(host, port)
  File "/usr/local/lib/python3.8/smtplib.py", line 339, in connect
    self.sock = self._get_socket(host, port, self.timeout)
  File "/usr/local/lib/python3.8/smtplib.py", line 310, in _get_socket
    return socket.create_connection((host, port), timeout,
  File "/usr/local/lib/python3.8/socket.py", line 808, in create_connection
    raise err
  File "/usr/local/lib/python3.8/socket.py", line 796, in create_connection
    sock.connect(sa)
ConnectionRefusedError: [Errno 111] Connection refused
[2024-11-26T15:57:31.147+0000] {taskinstance.py:1400} INFO - Marking task as FAILED. dag_id=drift_detection_dag, task_id=send_email, execution_date=20241124T160000, start_date=20241126T155730, end_date=20241126T155731
[2024-11-26T15:57:31.162+0000] {standard_task_runner.py:104} ERROR - Failed to execute job 9 for task send_email ([Errno 111] Connection refused; 328)
[2024-11-26T15:57:31.220+0000] {local_task_job_runner.py:228} INFO - Task exited with return code 1
[2024-11-26T15:57:31.255+0000] {taskinstance.py:2778} INFO - 0 downstream tasks scheduled from follow-on schedule check
