[2024-11-26T13:43:13.078+0000] {taskinstance.py:1159} INFO - Dependencies all met for dep_context=non-requeueable deps ti=<TaskInstance: drift_detection_dag.data_drift_detected manual__2024-11-26T13:42:57.442188+00:00 [queued]>
[2024-11-26T13:43:13.093+0000] {taskinstance.py:1159} INFO - Dependencies all met for dep_context=requeueable deps ti=<TaskInstance: drift_detection_dag.data_drift_detected manual__2024-11-26T13:42:57.442188+00:00 [queued]>
[2024-11-26T13:43:13.094+0000] {taskinstance.py:1361} INFO - Starting attempt 1 of 1
[2024-11-26T13:43:13.117+0000] {taskinstance.py:1382} INFO - Executing <Task(PythonOperator): data_drift_detected> on 2024-11-26 13:42:57.442188+00:00
[2024-11-26T13:43:13.128+0000] {standard_task_runner.py:57} INFO - Started process 505 to run task
[2024-11-26T13:43:13.133+0000] {standard_task_runner.py:84} INFO - Running: ['***', 'tasks', 'run', 'drift_detection_dag', 'data_drift_detected', 'manual__2024-11-26T13:42:57.442188+00:00', '--job-id', '13', '--raw', '--subdir', 'DAGS_FOLDER/drift-detection.py', '--cfg-path', '/tmp/tmpwjmiq23c']
[2024-11-26T13:43:13.138+0000] {standard_task_runner.py:85} INFO - Job 13: Subtask data_drift_detected
[2024-11-26T13:43:13.194+0000] {task_command.py:416} INFO - Running <TaskInstance: drift_detection_dag.data_drift_detected manual__2024-11-26T13:42:57.442188+00:00 [running]> on host 8e7793c99557
[2024-11-26T13:43:13.269+0000] {taskinstance.py:1662} INFO - Exporting env vars: AIRFLOW_CTX_DAG_OWNER='***' AIRFLOW_CTX_DAG_ID='drift_detection_dag' AIRFLOW_CTX_TASK_ID='data_drift_detected' AIRFLOW_CTX_EXECUTION_DATE='2024-11-26T13:42:57.442188+00:00' AIRFLOW_CTX_TRY_NUMBER='1' AIRFLOW_CTX_DAG_RUN_ID='manual__2024-11-26T13:42:57.442188+00:00'
[2024-11-26T13:43:13.325+0000] {warnings.py:109} WARNING - /home/***/.local/lib/python3.8/site-packages/numpy/lib/function_base.py:2854: RuntimeWarning: invalid value encountered in divide
  c /= stddev[:, None]

[2024-11-26T13:43:13.326+0000] {warnings.py:109} WARNING - /home/***/.local/lib/python3.8/site-packages/numpy/lib/function_base.py:2855: RuntimeWarning: invalid value encountered in divide
  c /= stddev[None, :]

[2024-11-26T13:43:13.330+0000] {warnings.py:109} WARNING - /home/***/.local/lib/python3.8/site-packages/numpy/lib/function_base.py:2854: RuntimeWarning: invalid value encountered in divide
  c /= stddev[:, None]

[2024-11-26T13:43:13.331+0000] {warnings.py:109} WARNING - /home/***/.local/lib/python3.8/site-packages/numpy/lib/function_base.py:2855: RuntimeWarning: invalid value encountered in divide
  c /= stddev[None, :]

[2024-11-26T13:43:13.442+0000] {warnings.py:109} WARNING - /home/***/.local/lib/python3.8/site-packages/numpy/lib/function_base.py:2854: RuntimeWarning: invalid value encountered in divide
  c /= stddev[:, None]

[2024-11-26T13:43:13.443+0000] {warnings.py:109} WARNING - /home/***/.local/lib/python3.8/site-packages/numpy/lib/function_base.py:2855: RuntimeWarning: invalid value encountered in divide
  c /= stddev[None, :]

[2024-11-26T13:43:13.447+0000] {warnings.py:109} WARNING - /home/***/.local/lib/python3.8/site-packages/numpy/lib/function_base.py:2854: RuntimeWarning: invalid value encountered in divide
  c /= stddev[:, None]

[2024-11-26T13:43:13.448+0000] {warnings.py:109} WARNING - /home/***/.local/lib/python3.8/site-packages/numpy/lib/function_base.py:2855: RuntimeWarning: invalid value encountered in divide
  c /= stddev[None, :]

[2024-11-26T13:43:13.621+0000] {python.py:194} INFO - Done. Returned value was: None
[2024-11-26T13:43:13.632+0000] {taskinstance.py:1400} INFO - Marking task as SUCCESS. dag_id=drift_detection_dag, task_id=data_drift_detected, execution_date=20241126T134257, start_date=20241126T134313, end_date=20241126T134313
[2024-11-26T13:43:13.667+0000] {local_task_job_runner.py:228} INFO - Task exited with return code 0
[2024-11-26T13:43:13.742+0000] {taskinstance.py:2778} INFO - 0 downstream tasks scheduled from follow-on schedule check
