[2024-11-26T01:33:32.407+0000] {taskinstance.py:1159} INFO - Dependencies all met for dep_context=non-requeueable deps ti=<TaskInstance: drift_detection_dag.clean_file manual__2024-11-26T01:33:10.022801+00:00 [queued]>
[2024-11-26T01:33:32.420+0000] {taskinstance.py:1159} INFO - Dependencies all met for dep_context=requeueable deps ti=<TaskInstance: drift_detection_dag.clean_file manual__2024-11-26T01:33:10.022801+00:00 [queued]>
[2024-11-26T01:33:32.421+0000] {taskinstance.py:1361} INFO - Starting attempt 1 of 1
[2024-11-26T01:33:32.438+0000] {taskinstance.py:1382} INFO - Executing <Task(PythonOperator): clean_file> on 2024-11-26 01:33:10.022801+00:00
[2024-11-26T01:33:32.448+0000] {standard_task_runner.py:57} INFO - Started process 7890 to run task
[2024-11-26T01:33:32.453+0000] {standard_task_runner.py:84} INFO - Running: ['***', 'tasks', 'run', 'drift_detection_dag', 'clean_file', 'manual__2024-11-26T01:33:10.022801+00:00', '--job-id', '47', '--raw', '--subdir', 'DAGS_FOLDER/drift-detection.py', '--cfg-path', '/tmp/tmpfy4fud8e']
[2024-11-26T01:33:32.459+0000] {standard_task_runner.py:85} INFO - Job 47: Subtask clean_file
[2024-11-26T01:33:32.523+0000] {task_command.py:416} INFO - Running <TaskInstance: drift_detection_dag.clean_file manual__2024-11-26T01:33:10.022801+00:00 [running]> on host 7f10b2294d44
[2024-11-26T01:33:32.631+0000] {taskinstance.py:1662} INFO - Exporting env vars: AIRFLOW_CTX_DAG_OWNER='***' AIRFLOW_CTX_DAG_ID='drift_detection_dag' AIRFLOW_CTX_TASK_ID='clean_file' AIRFLOW_CTX_EXECUTION_DATE='2024-11-26T01:33:10.022801+00:00' AIRFLOW_CTX_TRY_NUMBER='1' AIRFLOW_CTX_DAG_RUN_ID='manual__2024-11-26T01:33:10.022801+00:00'
[2024-11-26T01:33:32.648+0000] {taskinstance.py:1937} ERROR - Task failed with exception
Traceback (most recent call last):
  File "/home/airflow/.local/lib/python3.8/site-packages/airflow/operators/python.py", line 192, in execute
    return_value = self.execute_callable()
  File "/home/airflow/.local/lib/python3.8/site-packages/airflow/operators/python.py", line 209, in execute_callable
    return self.python_callable(*self.op_args, **self.op_kwargs)
  File "/opt/airflow/dags/drift-detection.py", line 93, in _clean_file
    os.remove(data_logs_filename)
PermissionError: [Errno 13] Permission denied: '/opt/airflow/data/data-drift/fraudTest-sample-drift.csv'
[2024-11-26T01:33:32.663+0000] {taskinstance.py:1400} INFO - Marking task as FAILED. dag_id=drift_detection_dag, task_id=clean_file, execution_date=20241126T013310, start_date=20241126T013332, end_date=20241126T013332
[2024-11-26T01:33:32.677+0000] {standard_task_runner.py:104} ERROR - Failed to execute job 47 for task clean_file ([Errno 13] Permission denied: '/opt/airflow/data/data-drift/fraudTest-sample-drift.csv'; 7890)
[2024-11-26T01:33:32.708+0000] {local_task_job_runner.py:228} INFO - Task exited with return code 1
[2024-11-26T01:33:32.753+0000] {taskinstance.py:2778} INFO - 0 downstream tasks scheduled from follow-on schedule check
