[2024-11-25T18:46:14.794+0000] {taskinstance.py:1159} INFO - Dependencies all met for dep_context=non-requeueable deps ti=<TaskInstance: drift_detection_dag.detect_data_drift scheduled__2024-11-24T16:00:00+00:00 [queued]>
[2024-11-25T18:46:14.805+0000] {taskinstance.py:1159} INFO - Dependencies all met for dep_context=requeueable deps ti=<TaskInstance: drift_detection_dag.detect_data_drift scheduled__2024-11-24T16:00:00+00:00 [queued]>
[2024-11-25T18:46:14.806+0000] {taskinstance.py:1361} INFO - Starting attempt 1 of 1
[2024-11-25T18:46:14.825+0000] {taskinstance.py:1382} INFO - Executing <Task(BranchPythonOperator): detect_data_drift> on 2024-11-24 16:00:00+00:00
[2024-11-25T18:46:14.835+0000] {standard_task_runner.py:57} INFO - Started process 3247 to run task
[2024-11-25T18:46:14.842+0000] {standard_task_runner.py:84} INFO - Running: ['***', 'tasks', 'run', 'drift_detection_dag', 'detect_data_drift', 'scheduled__2024-11-24T16:00:00+00:00', '--job-id', '8', '--raw', '--subdir', 'DAGS_FOLDER/drift-detection.py', '--cfg-path', '/tmp/tmprjsybh5z']
[2024-11-25T18:46:14.848+0000] {standard_task_runner.py:85} INFO - Job 8: Subtask detect_data_drift
[2024-11-25T18:46:14.907+0000] {task_command.py:416} INFO - Running <TaskInstance: drift_detection_dag.detect_data_drift scheduled__2024-11-24T16:00:00+00:00 [running]> on host 52f638c944a9
[2024-11-25T18:46:15.000+0000] {taskinstance.py:1662} INFO - Exporting env vars: AIRFLOW_CTX_DAG_OWNER='***' AIRFLOW_CTX_DAG_ID='drift_detection_dag' AIRFLOW_CTX_TASK_ID='detect_data_drift' AIRFLOW_CTX_EXECUTION_DATE='2024-11-24T16:00:00+00:00' AIRFLOW_CTX_TRY_NUMBER='1' AIRFLOW_CTX_DAG_RUN_ID='scheduled__2024-11-24T16:00:00+00:00'
[2024-11-25T18:46:15.048+0000] {taskinstance.py:1937} ERROR - Task failed with exception
Traceback (most recent call last):
  File "/home/airflow/.local/lib/python3.8/site-packages/airflow/operators/python.py", line 226, in execute
    branch = super().execute(context)
  File "/home/airflow/.local/lib/python3.8/site-packages/airflow/operators/python.py", line 192, in execute
    return_value = self.execute_callable()
  File "/home/airflow/.local/lib/python3.8/site-packages/airflow/operators/python.py", line 209, in execute_callable
    return self.python_callable(*self.op_args, **self.op_kwargs)
  File "/opt/airflow/dags/drift-detection.py", line 62, in _detect_data_drift
    reference, data_logs = _load_files(data_logs_filename)
  File "/opt/airflow/dags/drift-detection.py", line 39, in _load_files
    data_logs = pd.read_csv(data_logs_filename)
  File "/home/airflow/.local/lib/python3.8/site-packages/pandas/io/parsers/readers.py", line 912, in read_csv
    return _read(filepath_or_buffer, kwds)
  File "/home/airflow/.local/lib/python3.8/site-packages/pandas/io/parsers/readers.py", line 577, in _read
    parser = TextFileReader(filepath_or_buffer, **kwds)
  File "/home/airflow/.local/lib/python3.8/site-packages/pandas/io/parsers/readers.py", line 1407, in __init__
    self._engine = self._make_engine(f, self.engine)
  File "/home/airflow/.local/lib/python3.8/site-packages/pandas/io/parsers/readers.py", line 1661, in _make_engine
    self.handles = get_handle(
  File "/home/airflow/.local/lib/python3.8/site-packages/pandas/io/common.py", line 716, in get_handle
    ioargs = _get_filepath_or_buffer(
  File "/home/airflow/.local/lib/python3.8/site-packages/pandas/io/common.py", line 456, in _get_filepath_or_buffer
    raise ValueError(msg)
ValueError: Invalid file path or buffer object type: <class 'NoneType'>
[2024-11-25T18:46:15.077+0000] {taskinstance.py:1400} INFO - Marking task as FAILED. dag_id=drift_detection_dag, task_id=detect_data_drift, execution_date=20241124T160000, start_date=20241125T184614, end_date=20241125T184615
[2024-11-25T18:46:15.091+0000] {standard_task_runner.py:104} ERROR - Failed to execute job 8 for task detect_data_drift (Invalid file path or buffer object type: <class 'NoneType'>; 3247)
[2024-11-25T18:46:15.133+0000] {local_task_job_runner.py:228} INFO - Task exited with return code 1
[2024-11-25T18:46:15.151+0000] {taskinstance.py:2778} INFO - 0 downstream tasks scheduled from follow-on schedule check
[2024-11-25T21:03:37.776+0000] {taskinstance.py:1159} INFO - Dependencies all met for dep_context=non-requeueable deps ti=<TaskInstance: drift_detection_dag.detect_data_drift scheduled__2024-11-24T16:00:00+00:00 [queued]>
[2024-11-25T21:03:37.791+0000] {taskinstance.py:1159} INFO - Dependencies all met for dep_context=requeueable deps ti=<TaskInstance: drift_detection_dag.detect_data_drift scheduled__2024-11-24T16:00:00+00:00 [queued]>
[2024-11-25T21:03:37.792+0000] {taskinstance.py:1361} INFO - Starting attempt 1 of 1
[2024-11-25T21:03:37.813+0000] {taskinstance.py:1382} INFO - Executing <Task(BranchPythonOperator): detect_data_drift> on 2024-11-24 16:00:00+00:00
[2024-11-25T21:03:37.823+0000] {standard_task_runner.py:57} INFO - Started process 199 to run task
[2024-11-25T21:03:37.829+0000] {standard_task_runner.py:84} INFO - Running: ['***', 'tasks', 'run', 'drift_detection_dag', 'detect_data_drift', 'scheduled__2024-11-24T16:00:00+00:00', '--job-id', '5', '--raw', '--subdir', 'DAGS_FOLDER/drift-detection.py', '--cfg-path', '/tmp/tmplzxlgmxl']
[2024-11-25T21:03:37.834+0000] {standard_task_runner.py:85} INFO - Job 5: Subtask detect_data_drift
[2024-11-25T21:03:37.908+0000] {task_command.py:416} INFO - Running <TaskInstance: drift_detection_dag.detect_data_drift scheduled__2024-11-24T16:00:00+00:00 [running]> on host e252fbffc21c
[2024-11-25T21:03:38.009+0000] {taskinstance.py:1662} INFO - Exporting env vars: AIRFLOW_CTX_DAG_OWNER='***' AIRFLOW_CTX_DAG_ID='drift_detection_dag' AIRFLOW_CTX_TASK_ID='detect_data_drift' AIRFLOW_CTX_EXECUTION_DATE='2024-11-24T16:00:00+00:00' AIRFLOW_CTX_TRY_NUMBER='1' AIRFLOW_CTX_DAG_RUN_ID='scheduled__2024-11-24T16:00:00+00:00'
[2024-11-25T21:03:38.027+0000] {taskinstance.py:1937} ERROR - Task failed with exception
Traceback (most recent call last):
  File "/home/airflow/.local/lib/python3.8/site-packages/airflow/operators/python.py", line 226, in execute
    branch = super().execute(context)
  File "/home/airflow/.local/lib/python3.8/site-packages/airflow/operators/python.py", line 192, in execute
    return_value = self.execute_callable()
  File "/home/airflow/.local/lib/python3.8/site-packages/airflow/operators/python.py", line 209, in execute_callable
    return self.python_callable(*self.op_args, **self.op_kwargs)
  File "/opt/airflow/dags/drift-detection.py", line 59, in _detect_data_drift
    reference, data_logs = _load_files(data_logs_filename)
  File "/opt/airflow/dags/drift-detection.py", line 33, in _load_files
    reference = pd.read_csv("../data/reference/fraudTest-sample.csv")
  File "/home/airflow/.local/lib/python3.8/site-packages/pandas/io/parsers/readers.py", line 912, in read_csv
    return _read(filepath_or_buffer, kwds)
  File "/home/airflow/.local/lib/python3.8/site-packages/pandas/io/parsers/readers.py", line 577, in _read
    parser = TextFileReader(filepath_or_buffer, **kwds)
  File "/home/airflow/.local/lib/python3.8/site-packages/pandas/io/parsers/readers.py", line 1407, in __init__
    self._engine = self._make_engine(f, self.engine)
  File "/home/airflow/.local/lib/python3.8/site-packages/pandas/io/parsers/readers.py", line 1661, in _make_engine
    self.handles = get_handle(
  File "/home/airflow/.local/lib/python3.8/site-packages/pandas/io/common.py", line 859, in get_handle
    handle = open(
FileNotFoundError: [Errno 2] No such file or directory: '../data/reference/fraudTest-sample.csv'
[2024-11-25T21:03:38.045+0000] {taskinstance.py:1400} INFO - Marking task as FAILED. dag_id=drift_detection_dag, task_id=detect_data_drift, execution_date=20241124T160000, start_date=20241125T210337, end_date=20241125T210338
[2024-11-25T21:03:38.062+0000] {standard_task_runner.py:104} ERROR - Failed to execute job 5 for task detect_data_drift ([Errno 2] No such file or directory: '../data/reference/fraudTest-sample.csv'; 199)
[2024-11-25T21:03:38.120+0000] {local_task_job_runner.py:228} INFO - Task exited with return code 1
[2024-11-25T21:03:38.144+0000] {taskinstance.py:2778} INFO - 0 downstream tasks scheduled from follow-on schedule check
[2024-11-26T12:34:22.457+0000] {taskinstance.py:1159} INFO - Dependencies all met for dep_context=non-requeueable deps ti=<TaskInstance: drift_detection_dag.detect_data_drift scheduled__2024-11-24T16:00:00+00:00 [queued]>
[2024-11-26T12:34:22.472+0000] {taskinstance.py:1159} INFO - Dependencies all met for dep_context=requeueable deps ti=<TaskInstance: drift_detection_dag.detect_data_drift scheduled__2024-11-24T16:00:00+00:00 [queued]>
[2024-11-26T12:34:22.473+0000] {taskinstance.py:1361} INFO - Starting attempt 1 of 1
[2024-11-26T12:34:22.493+0000] {taskinstance.py:1382} INFO - Executing <Task(BranchPythonOperator): detect_data_drift> on 2024-11-24 16:00:00+00:00
[2024-11-26T12:34:22.502+0000] {standard_task_runner.py:57} INFO - Started process 198 to run task
[2024-11-26T12:34:22.508+0000] {standard_task_runner.py:84} INFO - Running: ['***', 'tasks', 'run', 'drift_detection_dag', 'detect_data_drift', 'scheduled__2024-11-24T16:00:00+00:00', '--job-id', '6', '--raw', '--subdir', 'DAGS_FOLDER/drift-detection.py', '--cfg-path', '/tmp/tmpjr8udem6']
[2024-11-26T12:34:22.516+0000] {standard_task_runner.py:85} INFO - Job 6: Subtask detect_data_drift
[2024-11-26T12:34:22.600+0000] {task_command.py:416} INFO - Running <TaskInstance: drift_detection_dag.detect_data_drift scheduled__2024-11-24T16:00:00+00:00 [running]> on host c359b096823c
[2024-11-26T12:34:22.721+0000] {taskinstance.py:1662} INFO - Exporting env vars: AIRFLOW_CTX_DAG_OWNER='***' AIRFLOW_CTX_DAG_ID='drift_detection_dag' AIRFLOW_CTX_TASK_ID='detect_data_drift' AIRFLOW_CTX_EXECUTION_DATE='2024-11-24T16:00:00+00:00' AIRFLOW_CTX_TRY_NUMBER='1' AIRFLOW_CTX_DAG_RUN_ID='scheduled__2024-11-24T16:00:00+00:00'
[2024-11-26T12:34:22.815+0000] {warnings.py:109} WARNING - /home/***/.local/lib/python3.8/site-packages/numpy/lib/function_base.py:2854: RuntimeWarning: invalid value encountered in divide
  c /= stddev[:, None]

[2024-11-26T12:34:22.816+0000] {warnings.py:109} WARNING - /home/***/.local/lib/python3.8/site-packages/numpy/lib/function_base.py:2855: RuntimeWarning: invalid value encountered in divide
  c /= stddev[None, :]

[2024-11-26T12:34:22.822+0000] {warnings.py:109} WARNING - /home/***/.local/lib/python3.8/site-packages/numpy/lib/function_base.py:2854: RuntimeWarning: invalid value encountered in divide
  c /= stddev[:, None]

[2024-11-26T12:34:22.823+0000] {warnings.py:109} WARNING - /home/***/.local/lib/python3.8/site-packages/numpy/lib/function_base.py:2855: RuntimeWarning: invalid value encountered in divide
  c /= stddev[None, :]

[2024-11-26T12:34:23.053+0000] {warnings.py:109} WARNING - /home/***/.local/lib/python3.8/site-packages/numpy/lib/function_base.py:2854: RuntimeWarning: invalid value encountered in divide
  c /= stddev[:, None]

[2024-11-26T12:34:23.056+0000] {warnings.py:109} WARNING - /home/***/.local/lib/python3.8/site-packages/numpy/lib/function_base.py:2855: RuntimeWarning: invalid value encountered in divide
  c /= stddev[None, :]

[2024-11-26T12:34:23.063+0000] {warnings.py:109} WARNING - /home/***/.local/lib/python3.8/site-packages/numpy/lib/function_base.py:2854: RuntimeWarning: invalid value encountered in divide
  c /= stddev[:, None]

[2024-11-26T12:34:23.064+0000] {warnings.py:109} WARNING - /home/***/.local/lib/python3.8/site-packages/numpy/lib/function_base.py:2855: RuntimeWarning: invalid value encountered in divide
  c /= stddev[None, :]

[2024-11-26T12:34:23.216+0000] {python.py:194} INFO - Done. Returned value was: data_drift_detected
[2024-11-26T12:34:23.216+0000] {python.py:227} INFO - Branch callable return data_drift_detected
[2024-11-26T12:34:23.217+0000] {skipmixin.py:173} INFO - Following branch data_drift_detected
[2024-11-26T12:34:23.244+0000] {skipmixin.py:239} INFO - Skipping tasks [('no_data_drift_detected', -1)]
[2024-11-26T12:34:23.325+0000] {taskinstance.py:1400} INFO - Marking task as SUCCESS. dag_id=drift_detection_dag, task_id=detect_data_drift, execution_date=20241124T160000, start_date=20241126T123422, end_date=20241126T123423
[2024-11-26T12:34:23.402+0000] {local_task_job_runner.py:228} INFO - Task exited with return code 0
[2024-11-26T12:34:23.463+0000] {taskinstance.py:2778} INFO - 1 downstream tasks scheduled from follow-on schedule check
[2024-11-26T13:40:19.909+0000] {taskinstance.py:1159} INFO - Dependencies all met for dep_context=non-requeueable deps ti=<TaskInstance: drift_detection_dag.detect_data_drift scheduled__2024-11-24T16:00:00+00:00 [queued]>
[2024-11-26T13:40:19.923+0000] {taskinstance.py:1159} INFO - Dependencies all met for dep_context=requeueable deps ti=<TaskInstance: drift_detection_dag.detect_data_drift scheduled__2024-11-24T16:00:00+00:00 [queued]>
[2024-11-26T13:40:19.924+0000] {taskinstance.py:1361} INFO - Starting attempt 1 of 1
[2024-11-26T13:40:19.942+0000] {taskinstance.py:1382} INFO - Executing <Task(BranchPythonOperator): detect_data_drift> on 2024-11-24 16:00:00+00:00
[2024-11-26T13:40:19.952+0000] {standard_task_runner.py:57} INFO - Started process 303 to run task
[2024-11-26T13:40:19.957+0000] {standard_task_runner.py:84} INFO - Running: ['***', 'tasks', 'run', 'drift_detection_dag', 'detect_data_drift', 'scheduled__2024-11-24T16:00:00+00:00', '--job-id', '6', '--raw', '--subdir', 'DAGS_FOLDER/drift-detection.py', '--cfg-path', '/tmp/tmpfw7e3nxg']
[2024-11-26T13:40:19.961+0000] {standard_task_runner.py:85} INFO - Job 6: Subtask detect_data_drift
[2024-11-26T13:40:20.024+0000] {task_command.py:416} INFO - Running <TaskInstance: drift_detection_dag.detect_data_drift scheduled__2024-11-24T16:00:00+00:00 [running]> on host 8e7793c99557
[2024-11-26T13:40:20.127+0000] {taskinstance.py:1662} INFO - Exporting env vars: AIRFLOW_CTX_DAG_OWNER='***' AIRFLOW_CTX_DAG_ID='drift_detection_dag' AIRFLOW_CTX_TASK_ID='detect_data_drift' AIRFLOW_CTX_EXECUTION_DATE='2024-11-24T16:00:00+00:00' AIRFLOW_CTX_TRY_NUMBER='1' AIRFLOW_CTX_DAG_RUN_ID='scheduled__2024-11-24T16:00:00+00:00'
[2024-11-26T13:40:20.195+0000] {warnings.py:109} WARNING - /home/***/.local/lib/python3.8/site-packages/numpy/lib/function_base.py:2854: RuntimeWarning: invalid value encountered in divide
  c /= stddev[:, None]

[2024-11-26T13:40:20.196+0000] {warnings.py:109} WARNING - /home/***/.local/lib/python3.8/site-packages/numpy/lib/function_base.py:2855: RuntimeWarning: invalid value encountered in divide
  c /= stddev[None, :]

[2024-11-26T13:40:20.199+0000] {warnings.py:109} WARNING - /home/***/.local/lib/python3.8/site-packages/numpy/lib/function_base.py:2854: RuntimeWarning: invalid value encountered in divide
  c /= stddev[:, None]

[2024-11-26T13:40:20.200+0000] {warnings.py:109} WARNING - /home/***/.local/lib/python3.8/site-packages/numpy/lib/function_base.py:2855: RuntimeWarning: invalid value encountered in divide
  c /= stddev[None, :]

[2024-11-26T13:40:20.300+0000] {warnings.py:109} WARNING - /home/***/.local/lib/python3.8/site-packages/numpy/lib/function_base.py:2854: RuntimeWarning: invalid value encountered in divide
  c /= stddev[:, None]

[2024-11-26T13:40:20.300+0000] {warnings.py:109} WARNING - /home/***/.local/lib/python3.8/site-packages/numpy/lib/function_base.py:2855: RuntimeWarning: invalid value encountered in divide
  c /= stddev[None, :]

[2024-11-26T13:40:20.303+0000] {warnings.py:109} WARNING - /home/***/.local/lib/python3.8/site-packages/numpy/lib/function_base.py:2854: RuntimeWarning: invalid value encountered in divide
  c /= stddev[:, None]

[2024-11-26T13:40:20.303+0000] {warnings.py:109} WARNING - /home/***/.local/lib/python3.8/site-packages/numpy/lib/function_base.py:2855: RuntimeWarning: invalid value encountered in divide
  c /= stddev[None, :]

[2024-11-26T13:40:20.402+0000] {python.py:194} INFO - Done. Returned value was: data_drift_detected
[2024-11-26T13:40:20.402+0000] {python.py:227} INFO - Branch callable return data_drift_detected
[2024-11-26T13:40:20.403+0000] {skipmixin.py:173} INFO - Following branch data_drift_detected
[2024-11-26T13:40:20.421+0000] {skipmixin.py:239} INFO - Skipping tasks [('no_data_drift_detected', -1)]
[2024-11-26T13:40:20.466+0000] {taskinstance.py:1400} INFO - Marking task as SUCCESS. dag_id=drift_detection_dag, task_id=detect_data_drift, execution_date=20241124T160000, start_date=20241126T134019, end_date=20241126T134020
[2024-11-26T13:40:20.529+0000] {local_task_job_runner.py:228} INFO - Task exited with return code 0
[2024-11-26T13:40:20.564+0000] {taskinstance.py:2778} INFO - 1 downstream tasks scheduled from follow-on schedule check
[2024-11-26T15:57:16.128+0000] {taskinstance.py:1159} INFO - Dependencies all met for dep_context=non-requeueable deps ti=<TaskInstance: drift_detection_dag.detect_data_drift scheduled__2024-11-24T16:00:00+00:00 [queued]>
[2024-11-26T15:57:16.141+0000] {taskinstance.py:1159} INFO - Dependencies all met for dep_context=requeueable deps ti=<TaskInstance: drift_detection_dag.detect_data_drift scheduled__2024-11-24T16:00:00+00:00 [queued]>
[2024-11-26T15:57:16.142+0000] {taskinstance.py:1361} INFO - Starting attempt 1 of 1
[2024-11-26T15:57:16.159+0000] {taskinstance.py:1382} INFO - Executing <Task(BranchPythonOperator): detect_data_drift> on 2024-11-24 16:00:00+00:00
[2024-11-26T15:57:16.169+0000] {standard_task_runner.py:57} INFO - Started process 264 to run task
[2024-11-26T15:57:16.173+0000] {standard_task_runner.py:84} INFO - Running: ['***', 'tasks', 'run', 'drift_detection_dag', 'detect_data_drift', 'scheduled__2024-11-24T16:00:00+00:00', '--job-id', '5', '--raw', '--subdir', 'DAGS_FOLDER/drift-detection.py', '--cfg-path', '/tmp/tmpm9xv54nr']
[2024-11-26T15:57:16.176+0000] {standard_task_runner.py:85} INFO - Job 5: Subtask detect_data_drift
[2024-11-26T15:57:16.243+0000] {task_command.py:416} INFO - Running <TaskInstance: drift_detection_dag.detect_data_drift scheduled__2024-11-24T16:00:00+00:00 [running]> on host e76aaec22df7
[2024-11-26T15:57:16.333+0000] {taskinstance.py:1662} INFO - Exporting env vars: AIRFLOW_CTX_DAG_OWNER='***' AIRFLOW_CTX_DAG_ID='drift_detection_dag' AIRFLOW_CTX_TASK_ID='detect_data_drift' AIRFLOW_CTX_EXECUTION_DATE='2024-11-24T16:00:00+00:00' AIRFLOW_CTX_TRY_NUMBER='1' AIRFLOW_CTX_DAG_RUN_ID='scheduled__2024-11-24T16:00:00+00:00'
[2024-11-26T15:57:16.431+0000] {warnings.py:109} WARNING - /home/***/.local/lib/python3.8/site-packages/numpy/lib/function_base.py:2854: RuntimeWarning: invalid value encountered in divide
  c /= stddev[:, None]

[2024-11-26T15:57:16.432+0000] {warnings.py:109} WARNING - /home/***/.local/lib/python3.8/site-packages/numpy/lib/function_base.py:2855: RuntimeWarning: invalid value encountered in divide
  c /= stddev[None, :]

[2024-11-26T15:57:16.435+0000] {warnings.py:109} WARNING - /home/***/.local/lib/python3.8/site-packages/numpy/lib/function_base.py:2854: RuntimeWarning: invalid value encountered in divide
  c /= stddev[:, None]

[2024-11-26T15:57:16.436+0000] {warnings.py:109} WARNING - /home/***/.local/lib/python3.8/site-packages/numpy/lib/function_base.py:2855: RuntimeWarning: invalid value encountered in divide
  c /= stddev[None, :]

[2024-11-26T15:57:16.541+0000] {warnings.py:109} WARNING - /home/***/.local/lib/python3.8/site-packages/numpy/lib/function_base.py:2854: RuntimeWarning: invalid value encountered in divide
  c /= stddev[:, None]

[2024-11-26T15:57:16.542+0000] {warnings.py:109} WARNING - /home/***/.local/lib/python3.8/site-packages/numpy/lib/function_base.py:2855: RuntimeWarning: invalid value encountered in divide
  c /= stddev[None, :]

[2024-11-26T15:57:16.544+0000] {warnings.py:109} WARNING - /home/***/.local/lib/python3.8/site-packages/numpy/lib/function_base.py:2854: RuntimeWarning: invalid value encountered in divide
  c /= stddev[:, None]

[2024-11-26T15:57:16.545+0000] {warnings.py:109} WARNING - /home/***/.local/lib/python3.8/site-packages/numpy/lib/function_base.py:2855: RuntimeWarning: invalid value encountered in divide
  c /= stddev[None, :]

[2024-11-26T15:57:16.625+0000] {python.py:194} INFO - Done. Returned value was: data_drift_detected
[2024-11-26T15:57:16.626+0000] {python.py:227} INFO - Branch callable return data_drift_detected
[2024-11-26T15:57:16.626+0000] {skipmixin.py:173} INFO - Following branch data_drift_detected
[2024-11-26T15:57:16.645+0000] {skipmixin.py:239} INFO - Skipping tasks [('no_data_drift_detected', -1)]
[2024-11-26T15:57:16.688+0000] {taskinstance.py:1400} INFO - Marking task as SUCCESS. dag_id=drift_detection_dag, task_id=detect_data_drift, execution_date=20241124T160000, start_date=20241126T155716, end_date=20241126T155716
[2024-11-26T15:57:16.747+0000] {local_task_job_runner.py:228} INFO - Task exited with return code 0
[2024-11-26T15:57:16.777+0000] {taskinstance.py:2778} INFO - 0 downstream tasks scheduled from follow-on schedule check
