[2024-11-25T21:14:44.606+0000] {taskinstance.py:1159} INFO - Dependencies all met for dep_context=non-requeueable deps ti=<TaskInstance: drift_detection_dag.detect_data_drift scheduled__2024-11-24T16:00:00+00:00 [queued]>
[2024-11-25T21:14:44.621+0000] {taskinstance.py:1159} INFO - Dependencies all met for dep_context=requeueable deps ti=<TaskInstance: drift_detection_dag.detect_data_drift scheduled__2024-11-24T16:00:00+00:00 [queued]>
[2024-11-25T21:14:44.621+0000] {taskinstance.py:1361} INFO - Starting attempt 2 of 2
[2024-11-25T21:14:44.637+0000] {taskinstance.py:1382} INFO - Executing <Task(BranchPythonOperator): detect_data_drift> on 2024-11-24 16:00:00+00:00
[2024-11-25T21:14:44.646+0000] {standard_task_runner.py:57} INFO - Started process 645 to run task
[2024-11-25T21:14:44.650+0000] {standard_task_runner.py:84} INFO - Running: ['***', 'tasks', 'run', 'drift_detection_dag', 'detect_data_drift', 'scheduled__2024-11-24T16:00:00+00:00', '--job-id', '9', '--raw', '--subdir', 'DAGS_FOLDER/drift-detection.py', '--cfg-path', '/tmp/tmpcfhq9tb8']
[2024-11-25T21:14:44.654+0000] {standard_task_runner.py:85} INFO - Job 9: Subtask detect_data_drift
[2024-11-25T21:14:44.714+0000] {task_command.py:416} INFO - Running <TaskInstance: drift_detection_dag.detect_data_drift scheduled__2024-11-24T16:00:00+00:00 [running]> on host e252fbffc21c
[2024-11-25T21:14:44.813+0000] {taskinstance.py:1662} INFO - Exporting env vars: AIRFLOW_CTX_DAG_OWNER='***' AIRFLOW_CTX_DAG_ID='drift_detection_dag' AIRFLOW_CTX_TASK_ID='detect_data_drift' AIRFLOW_CTX_EXECUTION_DATE='2024-11-24T16:00:00+00:00' AIRFLOW_CTX_TRY_NUMBER='2' AIRFLOW_CTX_DAG_RUN_ID='scheduled__2024-11-24T16:00:00+00:00'
[2024-11-25T21:14:44.824+0000] {logging_mixin.py:154} INFO - **************************************************** /opt/***
[2024-11-25T21:14:44.828+0000] {taskinstance.py:1937} ERROR - Task failed with exception
Traceback (most recent call last):
  File "/home/airflow/.local/lib/python3.8/site-packages/airflow/operators/python.py", line 226, in execute
    branch = super().execute(context)
  File "/home/airflow/.local/lib/python3.8/site-packages/airflow/operators/python.py", line 192, in execute
    return_value = self.execute_callable()
  File "/home/airflow/.local/lib/python3.8/site-packages/airflow/operators/python.py", line 209, in execute_callable
    return self.python_callable(*self.op_args, **self.op_kwargs)
  File "/opt/airflow/dags/drift-detection.py", line 60, in _detect_data_drift
    reference, data_logs = _load_files(data_logs_filename)
  File "/opt/airflow/dags/drift-detection.py", line 34, in _load_files
    reference = pd.read_csv("../data/reference/fraudTest-sample.csv")
  File "/home/airflow/.local/lib/python3.8/site-packages/pandas/io/parsers/readers.py", line 912, in read_csv
    return _read(filepath_or_buffer, kwds)
  File "/home/airflow/.local/lib/python3.8/site-packages/pandas/io/parsers/readers.py", line 577, in _read
    parser = TextFileReader(filepath_or_buffer, **kwds)
  File "/home/airflow/.local/lib/python3.8/site-packages/pandas/io/parsers/readers.py", line 1407, in __init__
    self._engine = self._make_engine(f, self.engine)
  File "/home/airflow/.local/lib/python3.8/site-packages/pandas/io/parsers/readers.py", line 1661, in _make_engine
    self.handles = get_handle(
  File "/home/airflow/.local/lib/python3.8/site-packages/pandas/io/common.py", line 859, in get_handle
    handle = open(
FileNotFoundError: [Errno 2] No such file or directory: '../data/reference/fraudTest-sample.csv'
[2024-11-25T21:14:44.841+0000] {taskinstance.py:1400} INFO - Marking task as FAILED. dag_id=drift_detection_dag, task_id=detect_data_drift, execution_date=20241124T160000, start_date=20241125T211444, end_date=20241125T211444
[2024-11-25T21:14:44.856+0000] {standard_task_runner.py:104} ERROR - Failed to execute job 9 for task detect_data_drift ([Errno 2] No such file or directory: '../data/reference/fraudTest-sample.csv'; 645)
[2024-11-25T21:14:44.903+0000] {local_task_job_runner.py:228} INFO - Task exited with return code 1
[2024-11-25T21:14:44.937+0000] {taskinstance.py:2778} INFO - 0 downstream tasks scheduled from follow-on schedule check
