[2024-11-25T18:46:14.794+0000] {taskinstance.py:1159} INFO - Dependencies all met for dep_context=non-requeueable deps ti=<TaskInstance: drift_detection_dag.detect_data_drift scheduled__2024-11-24T16:00:00+00:00 [queued]>
[2024-11-25T18:46:14.805+0000] {taskinstance.py:1159} INFO - Dependencies all met for dep_context=requeueable deps ti=<TaskInstance: drift_detection_dag.detect_data_drift scheduled__2024-11-24T16:00:00+00:00 [queued]>
[2024-11-25T18:46:14.806+0000] {taskinstance.py:1361} INFO - Starting attempt 1 of 1
[2024-11-25T18:46:14.825+0000] {taskinstance.py:1382} INFO - Executing <Task(BranchPythonOperator): detect_data_drift> on 2024-11-24 16:00:00+00:00
[2024-11-25T18:46:14.835+0000] {standard_task_runner.py:57} INFO - Started process 3247 to run task
[2024-11-25T18:46:14.842+0000] {standard_task_runner.py:84} INFO - Running: ['***', 'tasks', 'run', 'drift_detection_dag', 'detect_data_drift', 'scheduled__2024-11-24T16:00:00+00:00', '--job-id', '8', '--raw', '--subdir', 'DAGS_FOLDER/drift-detection.py', '--cfg-path', '/tmp/tmprjsybh5z']
[2024-11-25T18:46:14.848+0000] {standard_task_runner.py:85} INFO - Job 8: Subtask detect_data_drift
[2024-11-25T18:46:14.907+0000] {task_command.py:416} INFO - Running <TaskInstance: drift_detection_dag.detect_data_drift scheduled__2024-11-24T16:00:00+00:00 [running]> on host 52f638c944a9
[2024-11-25T18:46:15.000+0000] {taskinstance.py:1662} INFO - Exporting env vars: AIRFLOW_CTX_DAG_OWNER='***' AIRFLOW_CTX_DAG_ID='drift_detection_dag' AIRFLOW_CTX_TASK_ID='detect_data_drift' AIRFLOW_CTX_EXECUTION_DATE='2024-11-24T16:00:00+00:00' AIRFLOW_CTX_TRY_NUMBER='1' AIRFLOW_CTX_DAG_RUN_ID='scheduled__2024-11-24T16:00:00+00:00'
[2024-11-25T18:46:15.048+0000] {taskinstance.py:1937} ERROR - Task failed with exception
Traceback (most recent call last):
  File "/home/airflow/.local/lib/python3.8/site-packages/airflow/operators/python.py", line 226, in execute
    branch = super().execute(context)
  File "/home/airflow/.local/lib/python3.8/site-packages/airflow/operators/python.py", line 192, in execute
    return_value = self.execute_callable()
  File "/home/airflow/.local/lib/python3.8/site-packages/airflow/operators/python.py", line 209, in execute_callable
    return self.python_callable(*self.op_args, **self.op_kwargs)
  File "/opt/airflow/dags/drift-detection.py", line 62, in _detect_data_drift
    reference, data_logs = _load_files(data_logs_filename)
  File "/opt/airflow/dags/drift-detection.py", line 39, in _load_files
    data_logs = pd.read_csv(data_logs_filename)
  File "/home/airflow/.local/lib/python3.8/site-packages/pandas/io/parsers/readers.py", line 912, in read_csv
    return _read(filepath_or_buffer, kwds)
  File "/home/airflow/.local/lib/python3.8/site-packages/pandas/io/parsers/readers.py", line 577, in _read
    parser = TextFileReader(filepath_or_buffer, **kwds)
  File "/home/airflow/.local/lib/python3.8/site-packages/pandas/io/parsers/readers.py", line 1407, in __init__
    self._engine = self._make_engine(f, self.engine)
  File "/home/airflow/.local/lib/python3.8/site-packages/pandas/io/parsers/readers.py", line 1661, in _make_engine
    self.handles = get_handle(
  File "/home/airflow/.local/lib/python3.8/site-packages/pandas/io/common.py", line 716, in get_handle
    ioargs = _get_filepath_or_buffer(
  File "/home/airflow/.local/lib/python3.8/site-packages/pandas/io/common.py", line 456, in _get_filepath_or_buffer
    raise ValueError(msg)
ValueError: Invalid file path or buffer object type: <class 'NoneType'>
[2024-11-25T18:46:15.077+0000] {taskinstance.py:1400} INFO - Marking task as FAILED. dag_id=drift_detection_dag, task_id=detect_data_drift, execution_date=20241124T160000, start_date=20241125T184614, end_date=20241125T184615
[2024-11-25T18:46:15.091+0000] {standard_task_runner.py:104} ERROR - Failed to execute job 8 for task detect_data_drift (Invalid file path or buffer object type: <class 'NoneType'>; 3247)
[2024-11-25T18:46:15.133+0000] {local_task_job_runner.py:228} INFO - Task exited with return code 1
[2024-11-25T18:46:15.151+0000] {taskinstance.py:2778} INFO - 0 downstream tasks scheduled from follow-on schedule check
[2024-11-25T21:03:37.776+0000] {taskinstance.py:1159} INFO - Dependencies all met for dep_context=non-requeueable deps ti=<TaskInstance: drift_detection_dag.detect_data_drift scheduled__2024-11-24T16:00:00+00:00 [queued]>
[2024-11-25T21:03:37.791+0000] {taskinstance.py:1159} INFO - Dependencies all met for dep_context=requeueable deps ti=<TaskInstance: drift_detection_dag.detect_data_drift scheduled__2024-11-24T16:00:00+00:00 [queued]>
[2024-11-25T21:03:37.792+0000] {taskinstance.py:1361} INFO - Starting attempt 1 of 1
[2024-11-25T21:03:37.813+0000] {taskinstance.py:1382} INFO - Executing <Task(BranchPythonOperator): detect_data_drift> on 2024-11-24 16:00:00+00:00
[2024-11-25T21:03:37.823+0000] {standard_task_runner.py:57} INFO - Started process 199 to run task
[2024-11-25T21:03:37.829+0000] {standard_task_runner.py:84} INFO - Running: ['***', 'tasks', 'run', 'drift_detection_dag', 'detect_data_drift', 'scheduled__2024-11-24T16:00:00+00:00', '--job-id', '5', '--raw', '--subdir', 'DAGS_FOLDER/drift-detection.py', '--cfg-path', '/tmp/tmplzxlgmxl']
[2024-11-25T21:03:37.834+0000] {standard_task_runner.py:85} INFO - Job 5: Subtask detect_data_drift
[2024-11-25T21:03:37.908+0000] {task_command.py:416} INFO - Running <TaskInstance: drift_detection_dag.detect_data_drift scheduled__2024-11-24T16:00:00+00:00 [running]> on host e252fbffc21c
[2024-11-25T21:03:38.009+0000] {taskinstance.py:1662} INFO - Exporting env vars: AIRFLOW_CTX_DAG_OWNER='***' AIRFLOW_CTX_DAG_ID='drift_detection_dag' AIRFLOW_CTX_TASK_ID='detect_data_drift' AIRFLOW_CTX_EXECUTION_DATE='2024-11-24T16:00:00+00:00' AIRFLOW_CTX_TRY_NUMBER='1' AIRFLOW_CTX_DAG_RUN_ID='scheduled__2024-11-24T16:00:00+00:00'
[2024-11-25T21:03:38.027+0000] {taskinstance.py:1937} ERROR - Task failed with exception
Traceback (most recent call last):
  File "/home/airflow/.local/lib/python3.8/site-packages/airflow/operators/python.py", line 226, in execute
    branch = super().execute(context)
  File "/home/airflow/.local/lib/python3.8/site-packages/airflow/operators/python.py", line 192, in execute
    return_value = self.execute_callable()
  File "/home/airflow/.local/lib/python3.8/site-packages/airflow/operators/python.py", line 209, in execute_callable
    return self.python_callable(*self.op_args, **self.op_kwargs)
  File "/opt/airflow/dags/drift-detection.py", line 59, in _detect_data_drift
    reference, data_logs = _load_files(data_logs_filename)
  File "/opt/airflow/dags/drift-detection.py", line 33, in _load_files
    reference = pd.read_csv("../data/reference/fraudTest-sample.csv")
  File "/home/airflow/.local/lib/python3.8/site-packages/pandas/io/parsers/readers.py", line 912, in read_csv
    return _read(filepath_or_buffer, kwds)
  File "/home/airflow/.local/lib/python3.8/site-packages/pandas/io/parsers/readers.py", line 577, in _read
    parser = TextFileReader(filepath_or_buffer, **kwds)
  File "/home/airflow/.local/lib/python3.8/site-packages/pandas/io/parsers/readers.py", line 1407, in __init__
    self._engine = self._make_engine(f, self.engine)
  File "/home/airflow/.local/lib/python3.8/site-packages/pandas/io/parsers/readers.py", line 1661, in _make_engine
    self.handles = get_handle(
  File "/home/airflow/.local/lib/python3.8/site-packages/pandas/io/common.py", line 859, in get_handle
    handle = open(
FileNotFoundError: [Errno 2] No such file or directory: '../data/reference/fraudTest-sample.csv'
[2024-11-25T21:03:38.045+0000] {taskinstance.py:1400} INFO - Marking task as FAILED. dag_id=drift_detection_dag, task_id=detect_data_drift, execution_date=20241124T160000, start_date=20241125T210337, end_date=20241125T210338
[2024-11-25T21:03:38.062+0000] {standard_task_runner.py:104} ERROR - Failed to execute job 5 for task detect_data_drift ([Errno 2] No such file or directory: '../data/reference/fraudTest-sample.csv'; 199)
[2024-11-25T21:03:38.120+0000] {local_task_job_runner.py:228} INFO - Task exited with return code 1
[2024-11-25T21:03:38.144+0000] {taskinstance.py:2778} INFO - 0 downstream tasks scheduled from follow-on schedule check
