[2024-11-26T12:34:22.397+0000] {taskinstance.py:1159} INFO - Dependencies all met for dep_context=non-requeueable deps ti=<TaskInstance: drift_detection_dag.detect_data_drift manual__2024-11-26T12:34:06.338915+00:00 [queued]>
[2024-11-26T12:34:22.414+0000] {taskinstance.py:1159} INFO - Dependencies all met for dep_context=requeueable deps ti=<TaskInstance: drift_detection_dag.detect_data_drift manual__2024-11-26T12:34:06.338915+00:00 [queued]>
[2024-11-26T12:34:22.415+0000] {taskinstance.py:1361} INFO - Starting attempt 1 of 1
[2024-11-26T12:34:22.436+0000] {taskinstance.py:1382} INFO - Executing <Task(BranchPythonOperator): detect_data_drift> on 2024-11-26 12:34:06.338915+00:00
[2024-11-26T12:34:22.446+0000] {standard_task_runner.py:57} INFO - Started process 197 to run task
[2024-11-26T12:34:22.451+0000] {standard_task_runner.py:84} INFO - Running: ['***', 'tasks', 'run', 'drift_detection_dag', 'detect_data_drift', 'manual__2024-11-26T12:34:06.338915+00:00', '--job-id', '5', '--raw', '--subdir', 'DAGS_FOLDER/drift-detection.py', '--cfg-path', '/tmp/tmpupxr90fb']
[2024-11-26T12:34:22.458+0000] {standard_task_runner.py:85} INFO - Job 5: Subtask detect_data_drift
[2024-11-26T12:34:22.518+0000] {task_command.py:416} INFO - Running <TaskInstance: drift_detection_dag.detect_data_drift manual__2024-11-26T12:34:06.338915+00:00 [running]> on host c359b096823c
[2024-11-26T12:34:22.638+0000] {taskinstance.py:1662} INFO - Exporting env vars: AIRFLOW_CTX_DAG_OWNER='***' AIRFLOW_CTX_DAG_ID='drift_detection_dag' AIRFLOW_CTX_TASK_ID='detect_data_drift' AIRFLOW_CTX_EXECUTION_DATE='2024-11-26T12:34:06.338915+00:00' AIRFLOW_CTX_TRY_NUMBER='1' AIRFLOW_CTX_DAG_RUN_ID='manual__2024-11-26T12:34:06.338915+00:00'
[2024-11-26T12:34:22.778+0000] {warnings.py:109} WARNING - /home/***/.local/lib/python3.8/site-packages/numpy/lib/function_base.py:2854: RuntimeWarning: invalid value encountered in divide
  c /= stddev[:, None]

[2024-11-26T12:34:22.779+0000] {warnings.py:109} WARNING - /home/***/.local/lib/python3.8/site-packages/numpy/lib/function_base.py:2855: RuntimeWarning: invalid value encountered in divide
  c /= stddev[None, :]

[2024-11-26T12:34:22.783+0000] {warnings.py:109} WARNING - /home/***/.local/lib/python3.8/site-packages/numpy/lib/function_base.py:2854: RuntimeWarning: invalid value encountered in divide
  c /= stddev[:, None]

[2024-11-26T12:34:22.784+0000] {warnings.py:109} WARNING - /home/***/.local/lib/python3.8/site-packages/numpy/lib/function_base.py:2855: RuntimeWarning: invalid value encountered in divide
  c /= stddev[None, :]

[2024-11-26T12:34:22.951+0000] {warnings.py:109} WARNING - /home/***/.local/lib/python3.8/site-packages/numpy/lib/function_base.py:2854: RuntimeWarning: invalid value encountered in divide
  c /= stddev[:, None]

[2024-11-26T12:34:22.952+0000] {warnings.py:109} WARNING - /home/***/.local/lib/python3.8/site-packages/numpy/lib/function_base.py:2855: RuntimeWarning: invalid value encountered in divide
  c /= stddev[None, :]

[2024-11-26T12:34:22.956+0000] {warnings.py:109} WARNING - /home/***/.local/lib/python3.8/site-packages/numpy/lib/function_base.py:2854: RuntimeWarning: invalid value encountered in divide
  c /= stddev[:, None]

[2024-11-26T12:34:22.956+0000] {warnings.py:109} WARNING - /home/***/.local/lib/python3.8/site-packages/numpy/lib/function_base.py:2855: RuntimeWarning: invalid value encountered in divide
  c /= stddev[None, :]

[2024-11-26T12:34:23.155+0000] {python.py:194} INFO - Done. Returned value was: data_drift_detected
[2024-11-26T12:34:23.156+0000] {python.py:227} INFO - Branch callable return data_drift_detected
[2024-11-26T12:34:23.156+0000] {skipmixin.py:173} INFO - Following branch data_drift_detected
[2024-11-26T12:34:23.181+0000] {skipmixin.py:239} INFO - Skipping tasks [('no_data_drift_detected', -1)]
[2024-11-26T12:34:23.246+0000] {taskinstance.py:1400} INFO - Marking task as SUCCESS. dag_id=drift_detection_dag, task_id=detect_data_drift, execution_date=20241126T123406, start_date=20241126T123422, end_date=20241126T123423
[2024-11-26T12:34:23.307+0000] {local_task_job_runner.py:228} INFO - Task exited with return code 0
[2024-11-26T12:34:23.375+0000] {taskinstance.py:2778} INFO - 0 downstream tasks scheduled from follow-on schedule check
