[2024-11-25T23:16:14.950+0000] {taskinstance.py:1159} INFO - Dependencies all met for dep_context=non-requeueable deps ti=<TaskInstance: drift_detection_dag.data_drift_detected manual__2024-11-25T23:09:39.942879+00:00 [queued]>
[2024-11-25T23:16:15.004+0000] {taskinstance.py:1159} INFO - Dependencies all met for dep_context=requeueable deps ti=<TaskInstance: drift_detection_dag.data_drift_detected manual__2024-11-25T23:09:39.942879+00:00 [queued]>
[2024-11-25T23:16:15.005+0000] {taskinstance.py:1361} INFO - Starting attempt 1 of 1
[2024-11-25T23:16:15.044+0000] {taskinstance.py:1382} INFO - Executing <Task(PythonOperator): data_drift_detected> on 2024-11-25 23:09:39.942879+00:00
[2024-11-25T23:16:15.065+0000] {standard_task_runner.py:57} INFO - Started process 2618 to run task
[2024-11-25T23:16:15.072+0000] {standard_task_runner.py:84} INFO - Running: ['***', 'tasks', 'run', 'drift_detection_dag', 'data_drift_detected', 'manual__2024-11-25T23:09:39.942879+00:00', '--job-id', '19', '--raw', '--subdir', 'DAGS_FOLDER/drift-detection.py', '--cfg-path', '/tmp/tmp7imw9hle']
[2024-11-25T23:16:15.082+0000] {standard_task_runner.py:85} INFO - Job 19: Subtask data_drift_detected
[2024-11-25T23:16:15.180+0000] {task_command.py:416} INFO - Running <TaskInstance: drift_detection_dag.data_drift_detected manual__2024-11-25T23:09:39.942879+00:00 [running]> on host 7f10b2294d44
[2024-11-25T23:16:15.358+0000] {taskinstance.py:1662} INFO - Exporting env vars: AIRFLOW_CTX_DAG_OWNER='***' AIRFLOW_CTX_DAG_ID='drift_detection_dag' AIRFLOW_CTX_TASK_ID='data_drift_detected' AIRFLOW_CTX_EXECUTION_DATE='2024-11-25T23:09:39.942879+00:00' AIRFLOW_CTX_TRY_NUMBER='1' AIRFLOW_CTX_DAG_RUN_ID='manual__2024-11-25T23:09:39.942879+00:00'
[2024-11-25T23:16:15.381+0000] {logging_mixin.py:154} INFO - **************************************************** /opt/***
[2024-11-25T23:16:15.390+0000] {taskinstance.py:1937} ERROR - Task failed with exception
Traceback (most recent call last):
  File "/home/airflow/.local/lib/python3.8/site-packages/airflow/operators/python.py", line 192, in execute
    return_value = self.execute_callable()
  File "/home/airflow/.local/lib/python3.8/site-packages/airflow/operators/python.py", line 209, in execute_callable
    return self.python_callable(*self.op_args, **self.op_kwargs)
  File "/opt/airflow/dags/drift-detection.py", line 80, in _data_drift_detected
    reference, data_logs = _load_files(data_logs_filename)
  File "/opt/airflow/dags/drift-detection.py", line 34, in _load_files
    reference = pd.read_csv("../data/reference/fraudTest-sample.csv")
  File "/home/airflow/.local/lib/python3.8/site-packages/pandas/io/parsers/readers.py", line 912, in read_csv
    return _read(filepath_or_buffer, kwds)
  File "/home/airflow/.local/lib/python3.8/site-packages/pandas/io/parsers/readers.py", line 577, in _read
    parser = TextFileReader(filepath_or_buffer, **kwds)
  File "/home/airflow/.local/lib/python3.8/site-packages/pandas/io/parsers/readers.py", line 1407, in __init__
    self._engine = self._make_engine(f, self.engine)
  File "/home/airflow/.local/lib/python3.8/site-packages/pandas/io/parsers/readers.py", line 1661, in _make_engine
    self.handles = get_handle(
  File "/home/airflow/.local/lib/python3.8/site-packages/pandas/io/common.py", line 859, in get_handle
    handle = open(
FileNotFoundError: [Errno 2] No such file or directory: '../data/reference/fraudTest-sample.csv'
[2024-11-25T23:16:15.426+0000] {taskinstance.py:1400} INFO - Marking task as FAILED. dag_id=drift_detection_dag, task_id=data_drift_detected, execution_date=20241125T230939, start_date=20241125T231614, end_date=20241125T231615
[2024-11-25T23:16:15.484+0000] {standard_task_runner.py:104} ERROR - Failed to execute job 19 for task data_drift_detected ([Errno 2] No such file or directory: '../data/reference/fraudTest-sample.csv'; 2618)
[2024-11-25T23:16:15.539+0000] {local_task_job_runner.py:228} INFO - Task exited with return code 1
[2024-11-25T23:16:15.589+0000] {taskinstance.py:2778} INFO - 0 downstream tasks scheduled from follow-on schedule check
