[2024-11-26T13:40:32.251+0000] {taskinstance.py:1159} INFO - Dependencies all met for dep_context=non-requeueable deps ti=<TaskInstance: drift_detection_dag.send_email manual__2024-11-26T13:39:43.799596+00:00 [queued]>
[2024-11-26T13:40:32.261+0000] {taskinstance.py:1159} INFO - Dependencies all met for dep_context=requeueable deps ti=<TaskInstance: drift_detection_dag.send_email manual__2024-11-26T13:39:43.799596+00:00 [queued]>
[2024-11-26T13:40:32.262+0000] {taskinstance.py:1361} INFO - Starting attempt 1 of 1
[2024-11-26T13:40:32.279+0000] {taskinstance.py:1382} INFO - Executing <Task(EmailOperator): send_email> on 2024-11-26 13:39:43.799596+00:00
[2024-11-26T13:40:32.290+0000] {standard_task_runner.py:57} INFO - Started process 366 to run task
[2024-11-26T13:40:32.294+0000] {standard_task_runner.py:84} INFO - Running: ['***', 'tasks', 'run', 'drift_detection_dag', 'send_email', 'manual__2024-11-26T13:39:43.799596+00:00', '--job-id', '9', '--raw', '--subdir', 'DAGS_FOLDER/drift-detection.py', '--cfg-path', '/tmp/tmpzirj0nzm']
[2024-11-26T13:40:32.298+0000] {standard_task_runner.py:85} INFO - Job 9: Subtask send_email
[2024-11-26T13:40:32.348+0000] {task_command.py:416} INFO - Running <TaskInstance: drift_detection_dag.send_email manual__2024-11-26T13:39:43.799596+00:00 [running]> on host 8e7793c99557
[2024-11-26T13:40:32.424+0000] {taskinstance.py:1662} INFO - Exporting env vars: AIRFLOW_CTX_DAG_OWNER='***' AIRFLOW_CTX_DAG_ID='drift_detection_dag' AIRFLOW_CTX_TASK_ID='send_email' AIRFLOW_CTX_EXECUTION_DATE='2024-11-26T13:39:43.799596+00:00' AIRFLOW_CTX_TRY_NUMBER='1' AIRFLOW_CTX_DAG_RUN_ID='manual__2024-11-26T13:39:43.799596+00:00'
[2024-11-26T13:40:32.434+0000] {warnings.py:109} WARNING - /home/***/.local/lib/python3.8/site-packages/***/utils/email.py:154: RemovedInAirflow3Warning: Fetching SMTP credentials from configuration variables will be deprecated in a future release. Please set credentials using a connection instead.
  send_mime_email(e_from=mail_from, e_to=recipients, mime_msg=msg, conn_id=conn_id, dryrun=dryrun)

[2024-11-26T13:40:32.435+0000] {configuration.py:1050} WARNING - section/key [smtp/smtp_user] not found in config
[2024-11-26T13:40:32.436+0000] {email.py:270} INFO - Email alerting: attempt 1
[2024-11-26T13:40:32.437+0000] {taskinstance.py:1937} ERROR - Task failed with exception
Traceback (most recent call last):
  File "/home/airflow/.local/lib/python3.8/site-packages/airflow/operators/email.py", line 77, in execute
    send_email(
  File "/home/airflow/.local/lib/python3.8/site-packages/airflow/utils/email.py", line 80, in send_email
    return backend(
  File "/home/airflow/.local/lib/python3.8/site-packages/airflow/utils/email.py", line 154, in send_email_smtp
    send_mime_email(e_from=mail_from, e_to=recipients, mime_msg=msg, conn_id=conn_id, dryrun=dryrun)
  File "/home/airflow/.local/lib/python3.8/site-packages/airflow/utils/email.py", line 272, in send_mime_email
    smtp_conn = _get_smtp_connection(smtp_host, smtp_port, smtp_timeout, smtp_ssl)
  File "/home/airflow/.local/lib/python3.8/site-packages/airflow/utils/email.py", line 316, in _get_smtp_connection
    return smtplib.SMTP(host=host, port=port, timeout=timeout)
  File "/usr/local/lib/python3.8/smtplib.py", line 255, in __init__
    (code, msg) = self.connect(host, port)
  File "/usr/local/lib/python3.8/smtplib.py", line 339, in connect
    self.sock = self._get_socket(host, port, self.timeout)
  File "/usr/local/lib/python3.8/smtplib.py", line 310, in _get_socket
    return socket.create_connection((host, port), timeout,
  File "/usr/local/lib/python3.8/socket.py", line 808, in create_connection
    raise err
  File "/usr/local/lib/python3.8/socket.py", line 796, in create_connection
    sock.connect(sa)
ConnectionRefusedError: [Errno 111] Connection refused
[2024-11-26T13:40:32.445+0000] {taskinstance.py:1400} INFO - Marking task as FAILED. dag_id=drift_detection_dag, task_id=send_email, execution_date=20241126T133943, start_date=20241126T134032, end_date=20241126T134032
[2024-11-26T13:40:32.457+0000] {standard_task_runner.py:104} ERROR - Failed to execute job 9 for task send_email ([Errno 111] Connection refused; 366)
[2024-11-26T13:40:32.507+0000] {local_task_job_runner.py:228} INFO - Task exited with return code 1
[2024-11-26T13:40:32.534+0000] {taskinstance.py:2778} INFO - 0 downstream tasks scheduled from follow-on schedule check
