[2024-01-24 15:30:43,136] {taskinstance.py:1159} INFO - Dependencies all met for <TaskInstance: monitoring_dag.detect_data_drift manual__2024-01-24T15:27:34.555055+00:00 [queued]>
[2024-01-24 15:30:43,145] {taskinstance.py:1159} INFO - Dependencies all met for <TaskInstance: monitoring_dag.detect_data_drift manual__2024-01-24T15:27:34.555055+00:00 [queued]>
[2024-01-24 15:30:43,145] {taskinstance.py:1356} INFO - 
--------------------------------------------------------------------------------
[2024-01-24 15:30:43,145] {taskinstance.py:1357} INFO - Starting attempt 4 of 6
[2024-01-24 15:30:43,145] {taskinstance.py:1358} INFO - 
--------------------------------------------------------------------------------
[2024-01-24 15:30:43,154] {taskinstance.py:1377} INFO - Executing <Task(BranchPythonOperator): detect_data_drift> on 2024-01-24 15:27:34.555055+00:00
[2024-01-24 15:30:43,159] {standard_task_runner.py:52} INFO - Started process 825 to run task
[2024-01-24 15:30:43,162] {standard_task_runner.py:79} INFO - Running: ['***', 'tasks', 'run', 'monitoring_dag', 'detect_data_drift', 'manual__2024-01-24T15:27:34.555055+00:00', '--job-id', '36', '--raw', '--subdir', 'DAGS_FOLDER/monitoring-dag.py', '--cfg-path', '/tmp/tmpwxt806va', '--error-file', '/tmp/tmppd3aypp1']
[2024-01-24 15:30:43,162] {standard_task_runner.py:80} INFO - Job 36: Subtask detect_data_drift
[2024-01-24 15:30:43,198] {task_command.py:370} INFO - Running <TaskInstance: monitoring_dag.detect_data_drift manual__2024-01-24T15:27:34.555055+00:00 [running]> on host 7aa566990013
[2024-01-24 15:30:43,246] {taskinstance.py:1571} INFO - Exporting the following env vars:
AIRFLOW_CTX_DAG_OWNER=***
AIRFLOW_CTX_DAG_ID=monitoring_dag
AIRFLOW_CTX_TASK_ID=detect_data_drift
AIRFLOW_CTX_EXECUTION_DATE=2024-01-24T15:27:34.555055+00:00
AIRFLOW_CTX_TRY_NUMBER=4
AIRFLOW_CTX_DAG_RUN_ID=manual__2024-01-24T15:27:34.555055+00:00
[2024-01-24 15:30:43,279] {taskinstance.py:1889} ERROR - Task failed with exception
Traceback (most recent call last):
  File "/home/airflow/.local/lib/python3.7/site-packages/airflow/operators/python.py", line 207, in execute
    branch = super().execute(context)
  File "/home/airflow/.local/lib/python3.7/site-packages/airflow/operators/python.py", line 171, in execute
    return_value = self.execute_callable()
  File "/home/airflow/.local/lib/python3.7/site-packages/airflow/operators/python.py", line 189, in execute_callable
    return self.python_callable(*self.op_args, **self.op_kwargs)
  File "/opt/airflow/dags/monitoring-dag.py", line 66, in _detect_data_drift
    report = data_drift_report.as_dict()
  File "/home/airflow/.local/lib/python3.7/site-packages/evidently/report/report.py", line 168, in as_dict
    exclude=exclude.get(metric_id),
  File "/home/airflow/.local/lib/python3.7/site-packages/evidently/renderers/base_renderer.py", line 47, in render_json
    result = obj.get_result()
  File "/home/airflow/.local/lib/python3.7/site-packages/evidently/base_metric.py", line 223, in get_result
    raise result.exception
  File "/home/airflow/.local/lib/python3.7/site-packages/evidently/calculation_engine/engine.py", line 42, in execute_metrics
    calculations[metric] = calculation.calculate(context, converted_data)
  File "/home/airflow/.local/lib/python3.7/site-packages/evidently/calculation_engine/python_engine.py", line 88, in calculate
    return self.metric.calculate(data)
  File "/home/airflow/.local/lib/python3.7/site-packages/evidently/metrics/data_drift/dataset_drift_metric.py", line 97, in calculate
    agg_data=True,
  File "/home/airflow/.local/lib/python3.7/site-packages/evidently/calculations/data_drift.py", line 448, in get_drift_for_columns
    agg_data=agg_data,
  File "/home/airflow/.local/lib/python3.7/site-packages/evidently/calculations/data_drift.py", line 175, in get_one_column_drift
    current_correlations = current_data[numeric_columns].corr()[column_name].to_dict()
  File "/home/airflow/.local/lib/python3.7/site-packages/pandas/core/frame.py", line 3464, in __getitem__
    indexer = self.loc._get_listlike_indexer(key, axis=1)[1]
  File "/home/airflow/.local/lib/python3.7/site-packages/pandas/core/indexing.py", line 1314, in _get_listlike_indexer
    self._validate_read_indexer(keyarr, indexer, axis)
  File "/home/airflow/.local/lib/python3.7/site-packages/pandas/core/indexing.py", line 1377, in _validate_read_indexer
    raise KeyError(f"{not_found} not in index")
KeyError: "['count'] not in index"
[2024-01-24 15:30:43,287] {taskinstance.py:1400} INFO - Marking task as UP_FOR_RETRY. dag_id=monitoring_dag, task_id=detect_data_drift, execution_date=20240124T152734, start_date=20240124T153043, end_date=20240124T153043
[2024-01-24 15:30:43,296] {standard_task_runner.py:97} ERROR - Failed to execute job 36 for task detect_data_drift ("['count'] not in index"; 825)
[2024-01-24 15:30:43,334] {local_task_job.py:156} INFO - Task exited with return code 1
[2024-01-24 15:30:43,366] {local_task_job.py:273} INFO - 0 downstream tasks scheduled from follow-on schedule check
