[2024-01-24 15:39:46,284] {taskinstance.py:1159} INFO - Dependencies all met for <TaskInstance: monitoring_dag.clean_file manual__2024-01-24T15:38:36.527842+00:00 [queued]>
[2024-01-24 15:39:46,291] {taskinstance.py:1159} INFO - Dependencies all met for <TaskInstance: monitoring_dag.clean_file manual__2024-01-24T15:38:36.527842+00:00 [queued]>
[2024-01-24 15:39:46,291] {taskinstance.py:1356} INFO - 
--------------------------------------------------------------------------------
[2024-01-24 15:39:46,292] {taskinstance.py:1357} INFO - Starting attempt 2 of 6
[2024-01-24 15:39:46,292] {taskinstance.py:1358} INFO - 
--------------------------------------------------------------------------------
[2024-01-24 15:39:46,304] {taskinstance.py:1377} INFO - Executing <Task(PythonOperator): clean_file> on 2024-01-24 15:38:36.527842+00:00
[2024-01-24 15:39:46,309] {standard_task_runner.py:52} INFO - Started process 1346 to run task
[2024-01-24 15:39:46,312] {standard_task_runner.py:79} INFO - Running: ['***', 'tasks', 'run', 'monitoring_dag', 'clean_file', 'manual__2024-01-24T15:38:36.527842+00:00', '--job-id', '63', '--raw', '--subdir', 'DAGS_FOLDER/monitoring-dag.py', '--cfg-path', '/tmp/tmpl5v_tub6', '--error-file', '/tmp/tmp8yk03v9c']
[2024-01-24 15:39:46,313] {standard_task_runner.py:80} INFO - Job 63: Subtask clean_file
[2024-01-24 15:39:46,354] {task_command.py:370} INFO - Running <TaskInstance: monitoring_dag.clean_file manual__2024-01-24T15:38:36.527842+00:00 [running]> on host 7aa566990013
[2024-01-24 15:39:46,404] {taskinstance.py:1571} INFO - Exporting the following env vars:
AIRFLOW_CTX_DAG_OWNER=***
AIRFLOW_CTX_DAG_ID=monitoring_dag
AIRFLOW_CTX_TASK_ID=clean_file
AIRFLOW_CTX_EXECUTION_DATE=2024-01-24T15:38:36.527842+00:00
AIRFLOW_CTX_TRY_NUMBER=2
AIRFLOW_CTX_DAG_RUN_ID=manual__2024-01-24T15:38:36.527842+00:00
[2024-01-24 15:39:46,413] {taskinstance.py:1889} ERROR - Task failed with exception
Traceback (most recent call last):
  File "/home/airflow/.local/lib/python3.7/site-packages/airflow/operators/python.py", line 171, in execute
    return_value = self.execute_callable()
  File "/home/airflow/.local/lib/python3.7/site-packages/airflow/operators/python.py", line 189, in execute_callable
    return self.python_callable(*self.op_args, **self.op_kwargs)
  File "/opt/airflow/dags/monitoring-dag.py", line 94, in _clean_file
    os.remove(data_logs_filename)
FileNotFoundError: [Errno 2] No such file or directory: './data/data-drift/week1.csv'
[2024-01-24 15:39:46,421] {taskinstance.py:1400} INFO - Marking task as UP_FOR_RETRY. dag_id=monitoring_dag, task_id=clean_file, execution_date=20240124T153836, start_date=20240124T153946, end_date=20240124T153946
[2024-01-24 15:39:46,429] {standard_task_runner.py:97} ERROR - Failed to execute job 63 for task clean_file ([Errno 2] No such file or directory: './data/data-drift/week1.csv'; 1346)
[2024-01-24 15:39:46,444] {local_task_job.py:156} INFO - Task exited with return code 1
[2024-01-24 15:39:46,472] {local_task_job.py:273} INFO - 0 downstream tasks scheduled from follow-on schedule check
