[2024-01-24 15:38:44,579] {taskinstance.py:1159} INFO - Dependencies all met for <TaskInstance: monitoring_dag.clean_file manual__2024-01-24T15:38:36.527842+00:00 [queued]>
[2024-01-24 15:38:44,587] {taskinstance.py:1159} INFO - Dependencies all met for <TaskInstance: monitoring_dag.clean_file manual__2024-01-24T15:38:36.527842+00:00 [queued]>
[2024-01-24 15:38:44,588] {taskinstance.py:1356} INFO - 
--------------------------------------------------------------------------------
[2024-01-24 15:38:44,588] {taskinstance.py:1357} INFO - Starting attempt 1 of 6
[2024-01-24 15:38:44,588] {taskinstance.py:1358} INFO - 
--------------------------------------------------------------------------------
[2024-01-24 15:38:44,599] {taskinstance.py:1377} INFO - Executing <Task(PythonOperator): clean_file> on 2024-01-24 15:38:36.527842+00:00
[2024-01-24 15:38:44,604] {standard_task_runner.py:52} INFO - Started process 1292 to run task
[2024-01-24 15:38:44,608] {standard_task_runner.py:79} INFO - Running: ['***', 'tasks', 'run', 'monitoring_dag', 'clean_file', 'manual__2024-01-24T15:38:36.527842+00:00', '--job-id', '60', '--raw', '--subdir', 'DAGS_FOLDER/monitoring-dag.py', '--cfg-path', '/tmp/tmppg9wg_h7', '--error-file', '/tmp/tmpbl56p7y2']
[2024-01-24 15:38:44,608] {standard_task_runner.py:80} INFO - Job 60: Subtask clean_file
[2024-01-24 15:38:44,650] {task_command.py:370} INFO - Running <TaskInstance: monitoring_dag.clean_file manual__2024-01-24T15:38:36.527842+00:00 [running]> on host 7aa566990013
[2024-01-24 15:38:44,706] {taskinstance.py:1571} INFO - Exporting the following env vars:
AIRFLOW_CTX_DAG_OWNER=***
AIRFLOW_CTX_DAG_ID=monitoring_dag
AIRFLOW_CTX_TASK_ID=clean_file
AIRFLOW_CTX_EXECUTION_DATE=2024-01-24T15:38:36.527842+00:00
AIRFLOW_CTX_TRY_NUMBER=1
AIRFLOW_CTX_DAG_RUN_ID=manual__2024-01-24T15:38:36.527842+00:00
[2024-01-24 15:38:44,716] {taskinstance.py:1889} ERROR - Task failed with exception
Traceback (most recent call last):
  File "/home/airflow/.local/lib/python3.7/site-packages/airflow/operators/python.py", line 171, in execute
    return_value = self.execute_callable()
  File "/home/airflow/.local/lib/python3.7/site-packages/airflow/operators/python.py", line 189, in execute_callable
    return self.python_callable(*self.op_args, **self.op_kwargs)
  File "/opt/airflow/dags/monitoring-dag.py", line 94, in _clean_file
    os.remove(data_logs_filename)
FileNotFoundError: [Errno 2] No such file or directory: './data/data-drift/week1.csv'
[2024-01-24 15:38:44,723] {taskinstance.py:1400} INFO - Marking task as UP_FOR_RETRY. dag_id=monitoring_dag, task_id=clean_file, execution_date=20240124T153836, start_date=20240124T153844, end_date=20240124T153844
[2024-01-24 15:38:44,731] {standard_task_runner.py:97} ERROR - Failed to execute job 60 for task clean_file ([Errno 2] No such file or directory: './data/data-drift/week1.csv'; 1292)
[2024-01-24 15:38:44,739] {local_task_job.py:156} INFO - Task exited with return code 1
[2024-01-24 15:38:44,770] {local_task_job.py:273} INFO - 0 downstream tasks scheduled from follow-on schedule check
